Workbook

Sheet BUDGET 2025-2026
B8: Financial Budget for Academic year 2025-2026
B9: September | C9: October | D9: November | E9: December | F9: January | G9: February | H9: March | I9: April | J9: May | K9: June | L9: July | M9: August | N9: GENERAL TOTAL
B10: TOTAL | C10: TOTAL | D10: TOTAL | E10: TOTAL | F10: TOTAL | G10: TOTAL | H10: TOTAL | I10: TOTAL | J10: TOTAL | K10: TOTAL | L10: TOTAL | M10: TOTAL | N10: TOTAL
A11: Budgeted Number of Students | N11: ='INCOME DETAILS'!Q121 -> 4692
A12: Revenue
A13: Tuition Fees
A14: Faculty of Catechesis and Religious Sciences | B14: =N14/12 -> 5208333.3 | C14: 5208333.3 | D14: 5208333.3 | E14: 5208333.3 | F14: 5208333.3 | G14: 5208333.3 | H14: 5208333.3 | I14: 5208333.3 | J14: 5208333.3 | K14: 5208333.3 | L14: 5208333.3 | M14: 5208333.3 | N14: ='INCOME DETAILS'!AB104 -> 62500000
A15: Faculty of Commerce | B15: =N15/12 -> 17343750 | C15: 17343750 | D15: 17343750 | E15: 17343750 | F15: 17343750 | G15: 17343750 | H15: 17343750 | I15: 17343750 | J15: 17343750 | K15: 17343750 | L15: 17343750 | M15: 17343750 | N15: ='INCOME DETAILS'!AB112 -> 208125000
A16: Faculty of Education -under graduates | B16: =N16/12 -> 54873750 | C16: 54873750 | D16: 54873750 | E16: 54873750 | F16: 54873750 | G16: 54873750 | H16: 54873750 | I16: 54873750 | J16: 54873750 | K16: 54873750 | L16: 54873750 | M16: 54873750 | N16: ='INCOME DETAILS'!AB55 -> 658485000
A17: Faculty of Education -PGD- Taba campus-Kibungo Learning Center | B17: =N17/12 -> 2482666.7 | C17: 2482666.7 | D17: 2482666.7 | E17: 2482666.7 | F17: 2482666.7 | G17: 2482666.7 | H17: 2482666.7 | I17: 2482666.7 | J17: 2482666.7 | K17: 2482666.7 | L17: 2482666.7 | M17: 2482666.7 | N17: ='INCOME DETAILS'!AB117 -> 29792000
A18: Faculty of Public Health and Human Nutrition | B18: =N18/12 -> 17256667 | C18: 17256667 | D18: 17256667 | E18: 17256667 | F18: 17256667 | G18: 17256667 | H18: 17256667 | I18: 17256667 | J18: 17256667 | K18: 17256667 | L18: 17256667 | M18: 17256667 | N18: ='INCOME DETAILS'!AB96 -> 207080000
A19: Faculty of Science and Technology | B19: =N19/12 -> 7187500 | C19: 7187500 | D19: 7187500 | E19: 7187500 | F19: 7187500 | G19: 7187500 | H19: 7187500 | I19: 7187500 | J19: 7187500 | K19: 7187500 | L19: 7187500 | M19: 7187500 | N19: ='INCOME DETAILS'!AB21 -> 86250000
A20: Faculty of Social Work | B20: =N20/12 -> 4114583.3 | C20: 4114583.3 | D20: 4114583.3 | E20: 4114583.3 | F20: 4114583.3 | G20: 4114583.3 | H20: 4114583.3 | I20: 4114583.3 | J20: 4114583.3 | K20: 4114583.3 | L20: 4114583.3 | M20: 4114583.3 | N20: ='INCOME DETAILS'!AB29 -> 49375000
A21: Expected New Masters Program fees | K21: =N21/3 -> 5000000 | L21: 5000000 | M21: 5000000 | N21: ='INCOME DETAILS'!AB120 -> 15000000
A22: Ministry of health sponsored student
A23: Existing Sponsored | B23: =N23/12 -> 23065417 | C23: 23065417 | D23: 23065417 | E23: 23065417 | F23: 23065417 | G23: 23065417 | H23: 23065417 | I23: 23065417 | J23: 23065417 | K23: 23065417 | L23: 23065417 | M23: 23065417 | N23: 276785000
A24: Projected Sponsored | K24: =N24/3 -> 24625000 | L24: 24625000 | M24: 24625000 | N24: ='INCOME DETAILS'!S124 -> 73875000
A25: Chancen Student Tuition fees | B25: =N25/12 -> 32324778 | C25: 32324778 | D25: 32324778 | E25: 32324778 | F25: 32324778 | G25: 32324778 | H25: 32324778 | I25: 32324778 | J25: 32324778 | K25: 32324778 | L25: 32324778 | M25: 32324778 | N25: ='INCOME DETAILS'!F133 -> 3.8789733e+08
A26: YWCA | F26: =N26/9 -> 6007962.2 | G26: 6007962.2 | H26: 6007962.2 | I26: 6007962.2 | J26: 6007962.2 | K26: 6007962.2 | L26: 6007962.2 | M26: 6007962.2 | N26: ='INCOME DETAILS'!E140 -> 54071660
A27: Total Tuition fees | B27: =SUM(B14:B26) -> 1.6385744e+08 | C27: =SUM(C14:C26) -> 1.6385744e+08 | D27: =SUM(D14:D26) -> 1.6385744e+08 | E27: =SUM(E14:E26) -> 1.6385744e+08 | F27: =SUM(F14:F26) -> 1.6986541e+08 | G27: =SUM(G14:G26) -> 1.6986541e+08 | H27: =SUM(H14:H26) -> 1.6986541e+08 | I27: =SUM(I14:I26) -> 1.6986541e+08 | ... N27: =SUM(N14:N26) -> 2.109236e+09
A28: Application fees | B28: =N28/12 -> 795833.33 | C28: 795833.33 | D28: 795833.33 | E28: 795833.33 | F28: 795833.33 | G28: 795833.33 | H28: 795833.33 | I28: 795833.33 | J28: 795833.33 | K28: 795833.33 | L28: 795833.33 | M28: 795833.33 | N28: ='INCOME DETAILS'!AD121 -> 9550000
A29: Internship fees | B29: =N29/12 -> 2340000 | C29: 2340000 | D29: 2340000 | E29: 2340000 | F29: 2340000 | G29: 2340000 | H29: 2340000 | I29: 2340000 | J29: 2340000 | K29: 2340000 | L29: 2340000 | M29: 2340000 | N29: ='INCOME DETAILS'!AE121 -> 28080000
A30: Research supervision fees | B30: =N30/12 -> 2225000 | C30: 2225000 | D30: 2225000 | E30: 2225000 | F30: 2225000 | G30: 2225000 | H30: 2225000 | I30: 2225000 | J30: 2225000 | K30: 2225000 | L30: 2225000 | M30: 2225000 | N30: ='INCOME DETAILS'!AF121 -> 26700000
A31: Graduation fees | J31: =N31 -> 13000000 | N31: =260*50000 -> 13000000
A32: Fines | B32: =N32/12 -> 50820 | C32: 50820 | D32: 50820 | E32: 50820 | F32: 50820 | G32: 50820 | H32: 50820 | I32: 50820 | J32: 50820 | K32: 50820 | L32: 50820 | M32: 50820 | N32: 609840
A33: Retake fees | B33: =N33/12 -> 33333.333 | C33: 33333.333 | D33: 33333.333 | E33: 33333.333 | F33: 33333.333 | G33: 33333.333 | H33: 33333.333 | I33: 33333.333 | J33: 33333.333 | K33: 33333.333 | L33: 33333.333 | M33: 33333.333 | N33: 400000
A34: Academic documents fees | B34: =N34/12 -> 232466.67 | C34: 232466.67 | D34: 232466.67 | E34: 232466.67 | F34: 232466.67 | G34: 232466.67 | H34: 232466.67 | I34: 232466.67 | J34: 232466.67 | K34: 232466.67 | L34: 232466.67 | M34: 232466.67 | N34: 2789600
A35: Total academic cost | B35: =SUM(B27:B34) -> 1.695349e+08 | C35: =SUM(C27:C34) -> 1.695349e+08 | D35: =SUM(D27:D34) -> 1.695349e+08 | E35: =SUM(E27:E34) -> 1.695349e+08 | F35: =SUM(F27:F34) -> 1.7554286e+08 | G35: =SUM(G27:G34) -> 1.7554286e+08 | H35: =SUM(H27:H34) -> 1.7554286e+08 | I35: =SUM(I27:I34) -> 1.7554286e+08 | ... N35: =SUM(N27:N34) -> 2.1903654e+09
A37: Other Income
A38: Accomodation fee | B38: =N38/12 -> 1309000 | C38: 1309000 | D38: 1309000 | E38: 1309000 | F38: 1309000 | G38: 1309000 | H38: 1309000 | I38: 1309000 | J38: 1309000 | K38: 1309000 | L38: 1309000 | M38: 1309000 | N38: =187*7000*12 -> 15708000
A39: Other Income(Different IURA Projects) | F39: =N39/8 -> 12500000 | G39: 12500000 | H39: 12500000 | I39: 12500000 | J39: 12500000 | K39: 12500000 | L39: 12500000 | M39: 12500000 | N39: 100000000
A40: Total Income | B40: =B38+B39 -> 1309000 | C40: =C38+C39 -> 1309000 | D40: =D38+D39 -> 1309000 | E40: =E38+E39 -> 1309000 | F40: =F38+F39 -> 13809000 | G40: =G38+G39 -> 13809000 | H40: =H38+H39 -> 13809000 | I40: =I38+I39 -> 13809000 | ... N40: =N38+N39 -> 115708000
A41: TOTAL REVENUE(A) | B41: =B40+B35 -> 1.708439e+08 | C41: =C40+C35 -> 1.708439e+08 | D41: =D40+D35 -> 1.708439e+08 | E41: =E40+E35 -> 1.708439e+08 | F41: =F40+F35 -> 1.8935186e+08 | G41: =G40+G35 -> 1.8935186e+08 | H41: =H40+H35 -> 1.8935186e+08 | I41: =I40+I35 -> 1.8935186e+08 | ... N41: =N40+N35 -> 2.3060734e+09
A42: OPERATING EXPENSES
A43: Staff Cost
A44: Full timeTeaching staff | B44: =33807840.0605505*110% -> 37188624 | C44: =33807840.0605505*110% -> 37188624 | D44: =33807840.0605505*110% -> 37188624 | E44: =33807840.0605505*110% -> 37188624 | F44: =33807840.0605505*120% -> 40569408 | G44: =33807840.0605505*120% -> 40569408 | H44: =33807840.0605505*120% -> 40569408 | I44: =33807840.0605505*120% -> 40569408 | J44: =33807840.0605505*120% -> 40569408 | K44: =33807840.0605505*150% -> 50711760 | L44: =33807840.0605505*150% -> 50711760 | M44: =33807840.0605505*150% -> 50711760 | N44: =SUM(B44:M44) -> 5.0373682e+08
A45: Part time teaching staff | B45: =8392352.01821476*110% -> 9231587.2 | C45: =8392352.01821476*110% -> 9231587.2 | D45: =8392352.01821476*110% -> 9231587.2 | E45: =8392352.01821476*110% -> 9231587.2 | F45: =8392352.01821476*120% -> 10070822 | G45: =8392352.01821476*120% -> 10070822 | H45: =8392352.01821476*120% -> 10070822 | I45: =8392352.01821476*120% -> 10070822 | J45: =8392352.01821476*120% -> 10070822 | K45: =8392352.01821476*150% -> 12588528 | L45: =8392352.01821476*150% -> 12588528 | M45: =8392352.01821476*150% -> 12588528 | N45: =SUM(B45:M45) -> 1.2504605e+08
A46: Administrative + Support staff | B46: =15530409.8544533*110% -> 17083451 | C46: =15530409.8544533*110% -> 17083451 | D46: =15530409.8544533*110% -> 17083451 | E46: =15530409.8544533*110% -> 17083451 | F46: =15530409.8544533*120% -> 18636492 | G46: =15530409.8544533*120% -> 18636492 | H46: =15530409.8544533*120% -> 18636492 | I46: =15530409.8544533*120% -> 18636492 | J46: =15530409.8544533*120% -> 18636492 | K46: =15530409.8544533*150% -> 23295615 | L46: =15530409.8544533*150% -> 23295615 | M46: =15530409.8544533*150% -> 23295615 | N46: =SUM(B46:M46) -> 2.3140311e+08
A47: Other payment(Consultancy fees) | B47: =2974718.79640678*110% -> 3272190.7 | C47: =2974718.79640678*110% -> 3272190.7 | D47: =2974718.79640678*110% -> 3272190.7 | E47: =2974718.79640678*110% -> 3272190.7 | F47: =2974718.79640678*120% -> 3569662.6 | G47: =2974718.79640678*120% -> 3569662.6 | H47: =2974718.79640678*120% -> 3569662.6 | I47: =2974718.79640678*120% -> 3569662.6 | J47: =2974718.79640678*120% -> 3569662.6 | K47: =2974718.79640678*150% -> 4462078.2 | L47: =2974718.79640678*150% -> 4462078.2 | M47: =2974718.79640678*150% -> 4462078.2 | N47: =SUM(B47:M47) -> 44323310
A48: CPA staff | B48: =1251849.27037465*110% -> 1377034.2 | C48: =1251849.27037465*110% -> 1377034.2 | D48: =1251849.27037465*110% -> 1377034.2 | E48: =1251849.27037465*110% -> 1377034.2 | F48: =1251849.27037465*120% -> 1502219.1 | G48: =1251849.27037465*120% -> 1502219.1 | H48: =1251849.27037465*120% -> 1502219.1 | I48: =1251849.27037465*120% -> 1502219.1 | J48: =1251849.27037465*120% -> 1502219.1 | K48: =1251849.27037465*150% -> 1877773.9 | L48: =1251849.27037465*150% -> 1877773.9 | M48: =1251849.27037465*150% -> 1877773.9 | N48: =SUM(B48:M48) -> 18652554
...

Sheet presentation to Mgr
A1: BUDGET FOR ACADEMIC YEAR 2025-2026
N3: Number of students | O3: % Increase
A4: Number of student at start of 2025-2026 | N4: 3442
A5: Number of student Budgeted at end of 2025-2026 | N5: 4800
A6: Increase in number of student at year end | N6: =N5-N4 -> 1358 | O6: =N6/N4 -> 0.39453806
B8: Financial Budget for Academic year 2025-2026
B9: September | C9: October | D9: November | E9: December | F9: January | G9: February | H9: March | I9: April | J9: May | K9: June | L9: July | M9: August | N9: GENERAL TOTAL
B10: TOTAL | C10: TOTAL | D10: TOTAL | E10: TOTAL | F10: TOTAL | G10: TOTAL | H10: TOTAL | I10: TOTAL | J10: TOTAL | K10: TOTAL | L10: TOTAL | M10: TOTAL | N10: TOTAL
A11: Budgeted Number of Students | N11: 4800
A12: Revenue
A13: Tuition Fees
A14: Faculty of Catechesis and Religious Sciences | B14: =N14/12 -> 5208333.3 | C14: 5208333.3 | D14: 5208333.3 | E14: 5208333.3 | F14: 5208333.3 | G14: 5208333.3 | H14: 5208333.3 | I14: 5208333.3 | J14: 5208333.3 | K14: 5208333.3 | L14: 5208333.3 | M14: 5208333.3 | N14: ='INCOME DETAILS'!AB104 -> 62500000
A15: Faculty of Business studies | B15: =N15/12 -> 14843750 | C15: 17343750 | D15: 17343750 | E15: 17343750 | F15: 17343750 | G15: 17343750 | H15: 17343750 | I15: 17343750 | J15: 17343750 | K15: 17343750 | L15: 17343750 | M15: 17343750 | N15: 178125000
A16: Faculty of Education -under graduates | B16: =N16/12 -> 38207083 | C16: 46540417 | D16: 46540417 | E16: 46540417 | F16: 46540417 | G16: 46540417 | H16: 46540417 | I16: 46540417 | J16: 46540417 | K16: 46540417 | L16: 46540417 | M16: 46540417 | N16: 458485000
A17: Faculty of Education -PGD- Taba campus-Kibungo Learning Center | B17: =N17/12 -> 2482666.7 | C17: 2482666.7 | D17: 2482666.7 | E17: 2482666.7 | F17: 2482666.7 | G17: 2482666.7 | H17: 2482666.7 | I17: 2482666.7 | J17: 2482666.7 | K17: 2482666.7 | L17: 2482666.7 | M17: 2482666.7 | N17: ='INCOME DETAILS'!AB117 -> 29792000
A18: Faculty of Health Science | B18: =N18/12 -> 13090000 | C18: 17256667 | D18: 17256667 | E18: 17256667 | F18: 17256667 | G18: 17256667 | H18: 17256667 | I18: 17256667 | J18: 17256667 | K18: 17256667 | L18: 17256667 | M18: 17256667 | N18: 157080000
A19: Faculty of Science and Technology | B19: =N19/12 -> 7187500 | C19: 7187500 | D19: 7187500 | E19: 7187500 | F19: 7187500 | G19: 7187500 | H19: 7187500 | I19: 7187500 | J19: 7187500 | K19: 7187500 | L19: 7187500 | M19: 7187500 | N19: ='INCOME DETAILS'!AB21 -> 86250000
A20: Faculty of Social Work | B20: =N20/12 -> 4114583.3 | C20: 4114583.3 | D20: 4114583.3 | E20: 4114583.3 | F20: 4114583.3 | G20: 4114583.3 | H20: 4114583.3 | I20: 4114583.3 | J20: 4114583.3 | K20: 4114583.3 | L20: 4114583.3 | M20: 4114583.3 | N20: ='INCOME DETAILS'!AB29 -> 49375000
A21: Expected New Masters Program fees | K21: =N21/3 -> 5000000 | L21: 5000000 | M21: 5000000 | N21: ='INCOME DETAILS'!AB120 -> 15000000
A22: Ministry of health sponsored student
A23: Existing Sponsored | B23: =N23/12 -> 23065417 | C23: 23065417 | D23: 23065417 | E23: 23065417 | F23: 23065417 | G23: 23065417 | H23: 23065417 | I23: 23065417 | J23: 23065417 | K23: 23065417 | L23: 23065417 | M23: 23065417 | N23: 276785000
A24: Chancen Student Tuition fees | B24: =N24/12 -> 23991444 | C24: 32324778 | D24: 32324778 | E24: 32324778 | F24: 32324778 | G24: 32324778 | H24: 32324778 | I24: 32324778 | J24: 32324778 | K24: 32324778 | L24: 32324778 | M24: 32324778 | N24: 2.8789733e+08
A25: YWCA | F25: =N25/9 -> 6007962.2 | G25: 6007962.2 | H25: 6007962.2 | I25: 6007962.2 | J25: 6007962.2 | K25: 6007962.2 | L25: 6007962.2 | M25: 6007962.2 | N25: ='INCOME DETAILS'!E140 -> 54071660
A26: Total Tuition fees | B26: =SUM(B14:B25) -> 1.3219078e+08 | C26: =SUM(C14:C25) -> 1.5552411e+08 | D26: =SUM(D14:D25) -> 1.5552411e+08 | E26: =SUM(E14:E25) -> 1.5552411e+08 | F26: =SUM(F14:F25) -> 1.6153207e+08 | G26: =SUM(G14:G25) -> 1.6153207e+08 | H26: =SUM(H14:H25) -> 1.6153207e+08 | I26: =SUM(I14:I25) -> 1.6153207e+08 | ... N26: =SUM(N14:N25) -> 1.655361e+09
A27: Application fees | B27: =N27/12 -> 795833.33 | C27: 795833.33 | D27: 795833.33 | E27: 795833.33 | F27: 795833.33 | G27: 795833.33 | H27: 795833.33 | I27: 795833.33 | J27: 795833.33 | K27: 795833.33 | L27: 795833.33 | M27: 795833.33 | N27: ='INCOME DETAILS'!AD121 -> 9550000
A28: Internship fees | B28: =N28/12 -> 4840000 | C28: 2340000 | D28: 2340000 | E28: 2340000 | F28: 2340000 | G28: 2340000 | H28: 2340000 | I28: 2340000 | J28: 2340000 | K28: 2340000 | L28: 2340000 | M28: 2340000 | N28: 58080000
A29: Research supervision fees | B29: =N29/12 -> 2225000 | C29: 2225000 | D29: 2225000 | E29: 2225000 | F29: 2225000 | G29: 2225000 | H29: 2225000 | I29: 2225000 | J29: 2225000 | K29: 2225000 | L29: 2225000 | M29: 2225000 | N29: ='INCOME DETAILS'!AF121 -> 26700000
A30: Graduation fees | J30: =N30 -> 13000000 | N30: =260*50000 -> 13000000
A31: Fines | B31: =N31/12 -> 50820 | C31: 50820 | D31: 50820 | E31: 50820 | F31: 50820 | G31: 50820 | H31: 50820 | I31: 50820 | J31: 50820 | K31: 50820 | L31: 50820 | M31: 50820 | N31: 609840
A32: Retake fees | B32: =N32/12 -> 33333.333 | C32: 33333.333 | D32: 33333.333 | E32: 33333.333 | F32: 33333.333 | G32: 33333.333 | H32: 33333.333 | I32: 33333.333 | J32: 33333.333 | K32: 33333.333 | L32: 33333.333 | M32: 33333.333 | N32: 400000
A33: Academic documents fees | B33: =N33/12 -> 232466.67 | C33: 232466.67 | D33: 232466.67 | E33: 232466.67 | F33: 232466.67 | G33: 232466.67 | H33: 232466.67 | I33: 232466.67 | J33: 232466.67 | K33: 232466.67 | L33: 232466.67 | M33: 232466.67 | N33: 2789600
A34: Total academic cost | B34: =SUM(B26:B33) -> 1.4036823e+08 | C34: =SUM(C26:C33) -> 1.6120156e+08 | D34: =SUM(D26:D33) -> 1.6120156e+08 | E34: =SUM(E26:E33) -> 1.6120156e+08 | F34: =SUM(F26:F33) -> 1.6720953e+08 | G34: =SUM(G26:G33) -> 1.6720953e+08 | H34: =SUM(H26:H33) -> 1.6720953e+08 | I34: =SUM(I26:I33) -> 1.6720953e+08 | ... N34: =SUM(N26:N33) -> 1.7664904e+09
A35: Other Income
A36: Accomodation fee | B36: =N36/12 -> 7480000 | C36: 1309000 | D36: 1309000 | E36: 1309000 | F36: 1309000 | G36: 1309000 | H36: 1309000 | I36: 1309000 | J36: 1309000 | K36: 1309000 | L36: 1309000 | M36: 1309000 | N36: =187*40000*12 -> 89760000
A37: Income From research and Consultancy | N37: 100000000
A38: Income from Agricultural | N38: =1089876503.9/5 -> 2.179753e+08
A39: Other Income(Different IURA Projects) | F39: =N39/8 -> 25000000 | G39: 25000000 | H39: 25000000 | I39: 25000000 | J39: 25000000 | K39: 25000000 | L39: 25000000 | M39: 25000000 | N39: 200000000
A40: Total Income | B40: =B36+B39 -> 7480000 | C40: =C36+C39 -> 1309000 | D40: =D36+D39 -> 1309000 | E40: =E36+E39 -> 1309000 | F40: =F36+F39 -> 26309000 | G40: =G36+G39 -> 26309000 | H40: =H36+H39 -> 26309000 | I40: =I36+I39 -> 26309000 | ... M40: =M36+M39 -> 26309000 | N40: =N36+N39+N37+N38 -> 6.077353e+08
A41: TOTAL REVENUE(A) | B41: =B40+B34 -> 1.4784823e+08 | C41: =C40+C34 -> 1.6251056e+08 | D41: =D40+D34 -> 1.6251056e+08 | E41: =E40+E34 -> 1.6251056e+08 | F41: =F40+F34 -> 1.9351853e+08 | G41: =G40+G34 -> 1.9351853e+08 | H41: =H40+H34 -> 1.9351853e+08 | I41: =I40+I34 -> 1.9351853e+08 | ... N41: =N40+N34 -> 2.3742257e+09
A42: OPERATING EXPENSES
...

Sheet INCOME DETAILS
C1: Current Student | G1: Projected New student
G2: September 2025 Intake | J2: March 2026 Intake | M2: June 2026 Intake
C3: Day program | D3: Weekend Program | E3: Holiday Program | F3: Total Existing | G3: Day program | H3: Weekend Program | I3: Holiday Program | J3: Day program | K3: Weekend Program | L3: Holiday Program | M3: Day program | N3: Weekend Program | O3: Holiday Program | P3: Total Projected | Q3: Total Student Budgeted 2024-2025 | R3: Sponsored Student | AB3: Tuition fees | AC3: Registration fees+Technology fees | AD3: Application fees | AE3: Internship fees | AF3: Final project fees | AG3: Total
R4: Minisante | T4: Chancen | V4: YWCA | W4: Private student | X4: Existing private student | Y4: Projected Private
R5: Existing | S5: Projected | T5: Existing | U5: Projected | V5: Projected | Y5: Sept int | Z5: March In | AA5: June int
B6: 1.Faculty of science and technology
B7: 1.1 Department of computer science
B8: L8 S1&2 | C8: 60 | D8: 17 | F8: =SUM(C8:E8) -> 77 | G8: 10 | H8: 20 | I8: 0 | L8: 0 | O8: 0 | P8: =SUM(G8:O8) -> 30 | Q8: =F8+P8 -> 107 | T8: =21 -> 21 | U8: 50 | V8: 40 | W8: =Q8-SUM(R8:V8) -> -4 | X8: =F8-R8-T8 -> 56 | Z8: 10 | AB8: =((X8*375000)+(Y8*375000)+(Z8*250000)+(AA8*125000)) -> 23500000 | AC8: =W8*33000 -> -132000 | AD8: =W8*5000 -> -20000 | AG8: =SUM(AB8:AD8) -> 23348000
B9: L8 S3&4 | C9: 45 | D9: 23 | F9: =SUM(C9:E9) -> 68 | G9: 0 | H9: 0 | I9: 0 | J9: 0 | K9: 0 | L9: 0 | M9: 0 | N9: 0 | O9: 0 | P9: =SUM(G9:O9) -> 0 | Q9: =F9+P9 -> 68 | T9: 66 | W9: =Q9-SUM(R9:V9) -> 2 | X9: =F9-R9-T9 -> 2 | AG9: =SUM(AB9:AD9) -> 0
B10: L8 S5&6 | C10: 58 | D10: 9 | F10: =SUM(C10:E10) -> 67 | G10: 0 | H10: 10 | I10: 0 | J10: 0 | L10: 0 | M10: 0 | N10: 10 | O10: 0 | P10: =SUM(G10:O10) -> 20 | Q10: =F10+P10 -> 87 | W10: =Q10-SUM(R10:V10) -> 87 | X10: =F10-R10-T10 -> 67 | Z10: 10 | AA10: 10 | AB10: =((X10*375000)+(Y10*375000)+(Z10*250000)+(AA10*125000)) -> 28875000 | AC10: =W10*33000 -> 2871000 | AG10: =SUM(AB10:AD10) -> 31746000
B11: L8 S7&8 | C11: 6 | D11: 13 | F11: =SUM(C11:E11) -> 19 | G11: 0 | H11: 0 | I11: 0 | J11: 0 | K11: 0 | L11: 0 | M11: 0 | N11: 0 | O11: 0 | P11: =SUM(G11:O11) -> 0 | Q11: =F11+P11 -> 19 | W11: =Q11-SUM(R11:V11) -> 19 | X11: =F11-R11-T11 -> 19 | AB11: =((X11*375000)+(Y11*375000)+(Z11*250000)+(AA11*125000)) -> 7125000 | AC11: =W11*33000 -> 627000 | AE11: =W11*30000 -> 570000 | AF11: =W11*150000 -> 2850000 | AG11: =SUM(AB11:AD11) -> 7752000
B12: Graduands | F12: =SUM(C12:E12) -> 0 | G12: 0 | H12: 0 | I12: 0 | J12: 0 | K12: 0 | L12: 0 | M12: 0 | N12: 0 | O12: 0 | P12: =SUM(G12:O12) -> 0 | Q12: =F12+P12 -> 0 | X12: =F12-R12-T12 -> 0 | AB12: =((X12*375000)+(Y12*375000)+(Z12*250000)+(AA12*125000)) -> 0 | AC12: =W12*33000 -> 0
B13: Total Students in CS | C13: =SUM(C8:C12) -> 169 | D13: =SUM(D8:D12) -> 62 | F13: =SUM(F8:F12) -> 231 | G13: =SUM(G8:G12) -> 10 | H13: =SUM(H8:H12) -> 30 | I13: =SUM(I8:I12) -> 0 | J13: =SUM(J8:J12) -> 0 | K13: =SUM(K8:K12) -> 0 | L13: =SUM(L8:L12) -> 0 | M13: =SUM(M8:M12) -> 0 | ... AG13: =SUM(AG8:AG12) -> 62846000
B14: 1.2 Food processing Department
B15: L8 S1&2 | C15: 48 | D15: 0 | E15: 0 | F15: =SUM(C15:E15) -> 48 | G15: 40 | H15: 20 | I15: 0 | J15: 20 | K15: 20 | L15: 0 | P15: =SUM(G15:O15) -> 100 | Q15: =F15+P15 -> 148 | W15: =Q15-SUM(R15:V15) -> 148 | X15: =F15-R15-T15 -> 48 | AA15: 70 | AB15: =((X15*375000)+(Y15*375000)+(Z15*250000)+(AA15*125000)) -> 26750000 | AC15: =W15*33000 -> 4884000 | AD15: =W15*5000 -> 740000 | AG15: =SUM(AB15:AD15) -> 32374000
B16: L8 S3&4 | C16: 0 | D16: 0 | E16: 0 | F16: =SUM(C16:E16) -> 0 | G16: 0 | H16: 0 | I16: 0 | J16: 0 | K16: 0 | L16: 0 | M16: 0 | N16: 0 | O16: 0 | P16: =SUM(G16:O16) -> 0 | Q16: =F16+P16 -> 0 | W16: =Q16-SUM(R16:V16) -> 0 | X16: =F16-R16-T16 -> 0 | AC16: =W16*33000 -> 0 | AD16: =W16*5000 -> 0 | AE16: 0 | AF16: 0 | AG16: =SUM(AB16:AD16) -> 0
B17: L8 S5&6 | C17: 0 | D17: 0 | E17: 0 | F17: =SUM(C17:E17) -> 0 | G17: 0 | H17: 0 | I17: 0 | J17: 0 | K17: 0 | L17: 0 | M17: 0 | N17: 0 | O17: 0 | P17: =SUM(G17:O17) -> 0 | Q17: =F17+P17 -> 0 | W17: =Q17-SUM(R17:V17) -> 0 | X17: =F17-R17-T17 -> 0 | AC17: =W17*33000 -> 0 | AD17: =W17*5000 -> 0 | AE17: 0 | AF17: 0 | AG17: =SUM(AB17:AD17) -> 0
B18: L8 S7&8 | C18: 0 | D18: 0 | E18: 0 | F18: =SUM(C18:E18) -> 0 | G18: 0 | H18: 0 | I18: 0 | J18: 0 | K18: 0 | L18: 0 | M18: 0 | N18: 0 | O18: 0 | P18: =SUM(G18:O18) -> 0 | Q18: =F18+P18 -> 0 | W18: =Q18-SUM(R18:V18) -> 0 | X18: =F18-R18-T18 -> 0 | AC18: =W18*33000 -> 0 | AD18: =W18*5000 -> 0 | AE18: 0 | AF18: 0 | AG18: =SUM(AB18:AD18) -> 0
B19: Graduands | C19: 0 | D19: 0 | E19: 0 | F19: =SUM(C19:E19) -> 0 | G19: 0 | H19: 0 | I19: 0 | J19: 0 | K19: 0 | L19: 0 | M19: 0 | N19: 0 | O19: 0 | P19: =SUM(G19:O19) -> 0 | Q19: =F19+P19 -> 0 | W19: =Q19-SUM(R19:V19) -> 0 | X19: =F19-R19-T19 -> 0 | AC19: =W19*33000 -> 0 | AD19: =W19*5000 -> 0 | AE19: 0 | AF19: 0 | AG19: =SUM(AB19:AD19) -> 0
B20: Total Students in FP | C20: =SUM(C15:C19) -> 48 | D20: =SUM(D15:D19) -> 0 | E20: =SUM(E15:E19) -> 0 | F20: =SUM(F15:F19) -> 48 | G20: =SUM(G15:G19) -> 40 | H20: =SUM(H15:H19) -> 20 | I20: =SUM(I15:I19) -> 0 | J20: =SUM(J15:J19) -> 20 | ... AG20: =SUM(AG15:AG19) -> 32374000
B21: 1.Total Students in faculty of Science and technology | F21: =F13+F20 -> 279 | G21: =G13+G20 -> 50 | H21: =H13+H20 -> 50 | I21: =I13+I20 -> 0 | J21: =J13+J20 -> 20 | K21: =K13+K20 -> 20 | L21: =L13+L20 -> 0 | M21: =M13+M20 -> 0 | ... AG21: =AG13+AG20 -> 95220000
B22: 2.Faculty of social work | P22: =SUM(G22:O22) -> 0 | X22: =F22-R22-T22 -> 0
B23: L8 S1&2 | C23: 0 | F23: =SUM(C23:E23) -> 0 | H23: 10 | K23: 20 | N23: 10 | P23: =SUM(G23:O23) -> 40 | Q23: =F23+P23 -> 40 | W23: =Q23-SUM(R23:V23) -> 40 | X23: =F23-R23-T23 -> 0 | Y23: 10 | Z23: 20 | AA23: 10 | AB23: =((X23*375000)+(Y23*375000)+(Z23*250000)+(AA23*125000)) -> 10000000 | AC23: =W23*33000 -> 1320000 | AD23: =W23*5000 -> 200000 | AG23: =SUM(AB23:AD23) -> 11520000
B24: L8 S3&4 | C24: 0 | D24: 53 | E24: 0 | F24: =SUM(C24:E24) -> 53 | P24: =SUM(G24:O24) -> 0 | Q24: =F24+P24 -> 53 | W24: =Q24-SUM(R24:V24) -> 53 | X24: =F24-R24-T24 -> 53 | AB24: =((X24*375000)+(Y24*375000)+(Z24*250000)+(AA24*125000)) -> 19875000 | AC24: =W24*33000 -> 1749000 | AG24: =SUM(AB24:AD24) -> 21624000
B25: L8 S5&6 | C25: 0 | D25: 17 | E25: 0 | F25: =SUM(C25:E25) -> 17 | P25: =SUM(G25:O25) -> 0 | Q25: =F25+P25 -> 17 | W25: =Q25-SUM(R25:V25) -> 17 | X25: =F25-R25-T25 -> 17 | AB25: =((X25*375000)+(Y25*375000)+(Z25*250000)+(AA25*125000)) -> 6375000 | AC25: =W25*33000 -> 561000 | AG25: =SUM(AB25:AD25) -> 6936000
B26: L8 S7&8 | C26: 0 | D26: 21 | E26: 0 | F26: =SUM(C26:E26) -> 21 | P26: =SUM(G26:O26) -> 0 | Q26: =F26+P26 -> 21 | W26: =Q26-SUM(R26:V26) -> 21 | X26: =F26-R26-T26 -> 21 | AB26: =((X26*375000)+(Y26*375000)+(Z26*250000)+(AA26*125000)) -> 7875000 | AC26: =W26*33000 -> 693000 | AE26: =W26*30000 -> 630000 | AF26: =W26*150000 -> 3150000 | AG26: =SUM(AB26:AD26) -> 8568000
B27: Graduands | D27: 14 | E27: 0 | F27: =SUM(C27:E27) -> 14 | P27: =SUM(G27:O27) -> 0 | Q27: =F27+P27 -> 14 | W27: =Q27-SUM(R27:V27) -> 14 | X27: =F27-R27-T27 -> 14 | AB27: =((X27*375000)+(Y27*375000)+(Z27*250000)+(AA27*125000)) -> 5250000 | AC27: =W27*33000 -> 462000 | AG27: =SUM(AB27:AD27) -> 5712000
B28: Partime | C28: 0 | D28: 0 | E28: 0 | F28: =SUM(C28:E28) -> 0 | P28: =SUM(G28:O28) -> 0 | Q28: =F28+P28 -> 0 | W28: =Q28-SUM(R28:V28) -> 0 | X28: =F28-R28-T28 -> 0 | AB28: =((X28*375000)+(Y28*375000)+(Z28*250000)+(AA28*125000)) -> 0 | AC28: =W28*33000 -> 0 | AG28: =SUM(AB28:AD28) -> 0
B29: 2.Total students Faculty of social work | C29: 0 | D29: =SUM(D23:D28) -> 105 | F29: =SUM(F23:F28) -> 105 | G29: =SUM(G23:G28) -> 0 | H29: =SUM(H23:H28) -> 10 | I29: =SUM(I23:I28) -> 0 | J29: =SUM(J23:J28) -> 0 | K29: =SUM(K23:K28) -> 20 | L29: =SUM(L23:L28) -> 0 | M29: =SUM(M23:M28) -> 0 | ... AG29: =SUM(AG23:AG28) -> 54360000
B30: 3.Faculty of Education
B31: 3.1 Educational Management and planning | P31: =SUM(G31:O31) -> 0 | Q31: =F31+P31 -> 0 | X31: =F31-R31-T31 -> 0
B32: L8 S1&2 | C32: 1 | D32: 0 | F32: =SUM(C32:E32) -> 1 | P32: =SUM(G32:O32) -> 0 | Q32: =F32+P32 -> 1 | W32: =Q32-SUM(R32:V32) -> 1 | X32: =F32-R32-T32 -> 1 | AB32: =((X32*375000)+(Y32*375000)+(Z32*250000)+(AA32*125000)) -> 375000 | AC32: =W32*33000 -> 33000 | AD32: =W32*5000 -> 5000 | AG32: =SUM(AB32:AD32) -> 413000
B33: L8 S3&4 | C33: 0 | D33: 0 | F33: =SUM(C33:E33) -> 0 | P33: =SUM(G33:O33) -> 0 | Q33: =F33+P33 -> 0 | W33: =Q33-SUM(R33:V33) -> 0 | X33: =F33-R33-T33 -> 0 | AB33: =((X33*375000)+(Y33*375000)+(Z33*250000)+(AA33*125000)) -> 0 | AC33: =W33*33000 -> 0 | AG33: =SUM(AB33:AD33) -> 0
B34: L8 S5&6 | C34: 0 | D34: 0 | F34: =SUM(C34:E34) -> 0 | P34: =SUM(G34:O34) -> 0 | Q34: =F34+P34 -> 0 | W34: =Q34-SUM(R34:V34) -> 0 | X34: =F34-R34-T34 -> 0 | AB34: =((X34*375000)+(Y34*375000)+(Z34*250000)+(AA34*125000)) -> 0 | AC34: =W34*33000 -> 0 | AG34: =SUM(AB34:AD34) -> 0
B35: L8 S7&8 | C35: 0 | D35: 0 | F35: =SUM(C35:E35) -> 0 | P35: =SUM(G35:O35) -> 0 | Q35: =F35+P35 -> 0 | W35: =Q35-SUM(R35:V35) -> 0 | X35: =F35-R35-T35 -> 0 | AB35: =((X35*375000)+(Y35*375000)+(Z35*250000)+(AA35*125000)) -> 0 | AC35: =W35*33000 -> 0 | AE35: =W35*30000 -> 0 | AF35: =W35*150000 -> 0 | AG35: =SUM(AB35:AD35) -> 0
B36: Graduands | C36: 0 | D36: 0 | F36: =SUM(C36:E36) -> 0 | P36: =SUM(G36:O36) -> 0 | Q36: =F36+P36 -> 0 | W36: =Q36-SUM(R36:V36) -> 0 | X36: =F36-R36-T36 -> 0 | AB36: =((X36*375000)+(Y36*375000)+(Z36*250000)+(AA36*125000)) -> 0 | AC36: =W36*33000 -> 0 | AG36: =SUM(AB36:AD36) -> 0
B37: Partime | C37: 0 | D37: 0 | F37: =SUM(C37:E37) -> 0 | P37: =SUM(G37:O37) -> 0 | Q37: =F37+P37 -> 0 | W37: =Q37-SUM(R37:V37) -> 0 | X37: =F37-R37-T37 -> 0 | AB37: =((X37*375000)+(Y37*375000)+(Z37*250000)+(AA37*125000)) -> 0 | AC37: =W37*33000 -> 0 | AG37: =SUM(AB37:AD37) -> 0
B38: Total students | F38: =SUM(F32:F37) -> 1 | G38: =SUM(G32:G37) -> 0 | H38: =SUM(H32:H37) -> 0 | I38: =SUM(I32:I37) -> 0 | J38: =SUM(J32:J37) -> 0 | K38: =SUM(K32:K37) -> 0 | L38: =SUM(L32:L37) -> 0 | M38: =SUM(M32:M37) -> 0 | ... AG38: =SUM(AG32:AG37) -> 413000
B39: 3.2 Department of art and social science
B40: L8 S1&2 | C40: 94 | D40: 53 | E40: 86 | F40: =SUM(C40:E40) -> 233 | G40: 10 | H40: 20 | I40: 20 | J40: 10 | M40: 10 | N40: 20 | O40: 20 | P40: =SUM(G40:O40) -> 110 | Q40: =F40+P40 -> 343 | T40: 25 | W40: =Q40-SUM(R40:V40) -> 318 | X40: =F40-R40-T40 -> 208 | Y40: 90 | Z40: 70 | AA40: 90 | AB40: =(((E40*330000)+(I40*330000)+(L40*220000)+(O40*110000))+((C40-T40)*500000)+(D40*375000)+(G40*500000)+(H40*375000)+((J40-U40)*375000)+(K40*250000)+(M40*250000)+(N40*125000)) -> 112805000 | AC40: =W40*33000 -> 10494000 | AD40: =W40*5000 -> 1590000 | AG40: =SUM(AB40:AD40) -> 124889000
...

Sheet Sheet2
A1: FHS | B1: 1300
A2: FED | B2: 2500
A3: FST | B3: 440
A4: FCRS | B4: 150
A5: FSW | B5: 160
A6: FBS | B6: 1100
A7: Post graduate studies | B7: 100
B8: =SUM(B1:B7) -> 5750
B9: 3442 | C9: =B8-B9 -> 2308 | D9: 819 | E9: =D9/C9 -> 0.35485269

Sheet DETAILED Number of students
C2: L8 S1&2 | D2: L8 S3&4 | E2: L8 S5&6 | F2: L8 S7&8 | G2: L9 | H2: Graduands | I2: Partime | J2: Total students
A3: 1.Faculty of science and technology
A5: Department Biomedical Laboratory science | B5: Day program | C5: 22 | D5: 26 | E5: 76 | F5: 18 | I5: 0 | J5: =SUM(C5:I5) -> 142
B6: Weekend Program | C6: 0 | D6: 0 | E6: 0 | F6: 0 | I6: 0 | J6: =SUM(C6:I6) -> 0
A7: Department of computer science | B7: Day program | C7: =35+4 -> 39 | D7: 63 | E7: 8 | F7: 17 | J7: =SUM(C7:I7) -> 127
B8: Weekend Program | C8: 23 | E8: 20 | F8: 19 | J8: =SUM(C8:I8) -> 62
J9: =SUM(J5:J8) -> 331
A10: 2.Faculty of social work | B10: Day program | C10: 0 | D10: 0 | E10: 0 | F10: 0 | I10: 0 | J10: 0
B11: Weekend Program | C11: 34 | D11: 0 | E11: 14 | F11: 14 | I11: 0 | J11: =SUM(C11:I11) -> 62 | K11: =J11-'INCOME DETAILS'!#REF! -> #REF!
J12: =SUM(J10:J11) -> 62
A13: 3.Faculty of Education
A14: Educational Management and planning | B14: Day program | C14: 0 | D14: 0 | E14: 0 | F14: 0 | G14: 0 | H14: 0 | I14: 0
B15: Weekend Program | C15: 0 | D15: 0 | E15: 0 | F15: 0 | G15: 0 | H15: 0 | I15: 0
B16: Holiday program | C16: 0 | D16: 0 | E16: 0 | F16: 0 | G16: 0 | H16: 0 | I16: 0
A17: Department of art and social science | B17: Day program | C17: 38 | D17: 98 | J17: 136
B18: Weekend Program | C18: 63 | D18: 17 | E18: 16 | F18: 12 | H18: 12 | J18: 120
B19: Holiday program | C19: 140 | E19: 5 | F19: 8 | H19: 8 | J19: 161 | K19: 137
A20: Department of Science | B20: Day program | C20: 54 | D20: 113 | J20: 167 | K20: =J17+J20 -> 303
B21: Weekend Program | C21: 16 | D21: 48 | E21: 56 | F21: 33 | H21: 33 | J21: 186 | K21: =K20-K19 -> 166
B22: Holiday program | C22: 137 | E22: 69 | F22: 47 | H22: 47 | J22: 300
A23: 4.Faculty of public health and Human Nutrition | J23: =SUM(J14:J22) -> 1070
A24: Public Health | B24: Day program | E24: 16 | F24: 45 | J24: =SUM(C24:I24) -> 61
B25: Weekend Program | J25: =SUM(C25:I25) -> 0
A26: Human Nutrition | B26: Day program | D26: 5 | J26: =SUM(C26:I26) -> 5
B27: Weekend Program | J27: =SUM(C27:I27) -> 0
A28: Nursing | B28: Day program | C28: =43+40 -> 83 | J28: =SUM(C28:I28) -> 83
B29: Weekend Program | J29: =SUM(C29:I29) -> 0
A30: Midwifery | B30: Day program | C30: =100+100 -> 200 | J30: =SUM(C30:I30) -> 200
B31: Weekend Program | J31: =SUM(C31:I31) -> 0
J32: =SUM(J24:J31) -> 349
A33: 5. Faculty of Catechesis | B33: Day program | C33: 57 | D33: 0 | E33: 30 | F33: 32 | I33: 1 | J33: =SUM(C33:I33) -> 120
B34: Weekend Program | C34: 0 | D34: 0 | E34: 0 | F34: 0 | J34: =SUM(C34:I34) -> 0
J35: =SUM(J33:J34) -> 120
A36: 6.Faculty of commerce | B36: Day program | C36: 40 | D36: 113 | H36: 18 | J36: =SUM(C36:I36) -> 171
B37: Weekend Program | C37: 27 | D37: 101 | E37: 48 | F37: 74 | H37: 62 | J37: =SUM(C37:I37) -> 312
J38: =SUM(J36:J37) -> 483
A39: 7.Postgraduate students
B40: Huye campus | G40: 70 | J40: =SUM(G40:I40) -> 70
B41: Ngoma Learning center | G41: 7 | J41: =SUM(G41:I41) -> 7
J42: =SUM(J40:J41) -> 77
...

Sheet Sheet1
C2: L8 S1&2 | D2: L8 S3&4 | E2: L8 S5&6 | F2: L8 S7&8 | G2: L9 | H2: Graduands | I2: Partime | J2: Total students
A3: 3.Faculty of Education
A4: Educational Management and planning | B4: Day program | C4: 0 | D4: 0 | E4: 0 | F4: 0 | G4: 0 | H4: 0 | I4: 0
B5: Weekend Program | C5: 0 | D5: 0 | E5: 0 | F5: 0 | G5: 0 | H5: 0 | I5: 0
B6: Holiday program | C6: 0 | D6: 0 | E6: 0 | F6: 0 | G6: 0 | H6: 0 | I6: 0
A7: Department of art and social science | B7: Day program | C7: 38 | D7: 98 | J7: 136
B8: Weekend Program | C8: 63 | D8: 17 | E8: 16 | F8: 12 | H8: 12 | J8: 120
B9: Holiday program | C9: 140 | E9: 5 | F9: 8 | H9: 8 | J9: 161
A10: Department of Science | B10: Day program | C10: 54 | D10: 113 | J10: 167
B11: Weekend Program | C11: 16 | D11: 48 | E11: 56 | F11: 33 | H11: 33 | J11: 186
B12: Holiday program | C12: 137 | E12: 69 | F12: 47 | H12: 47 | J12: 300
D16: 3.Faculty of Education | E16: Educational Management and planning | H16: Department of art and social science | K16: Department of Science
E17: Day program | F17: Weekend Program | G17: Holiday program | H17: Day program | I17: Weekend Program | J17: Holiday program | K17: Day program | L17: Weekend Program | M17: Holiday program
C18: L8 S1&2 | E18: 0 | F18: 0 | G18: 0 | H18: 38 | I18: 63 | J18: 140 | K18: 54 | L18: 16 | M18: 137
C19: L8 S3&4 | E19: 0 | F19: 0 | G19: 0 | H19: 98 | I19: 17 | K19: 113 | L19: 48
C20: L8 S5&6 | E20: 0 | F20: 0 | G20: 0 | I20: 16 | J20: 5 | L20: 56 | M20: 69
C21: L8 S7&8 | E21: 0 | F21: 0 | G21: 0 | I21: 12 | J21: 8 | L21: 33 | M21: 47
C22: L9 | E22: 0 | F22: 0 | G22: 0
C23: Graduands | E23: 0 | F23: 0 | G23: 0 | I23: 12 | J23: 8 | L23: 33 | M23: 47
C24: Partime | E24: 0 | F24: 0 | G24: 0
C25: Total students | H25: 136 | I25: 120 | J25: 161 | K25: 167 | L25: 186 | M25: 300

Sheet Communication fees
A1: Communication fee Policy
A2: Rector | B2: =20000*2 -> 40000
A3: Vice-Rector | B3: 20000
A4: DAF | B4: 20000
A5: DOQ | B5: 15000
A6: Dean of FCRS | B6: 10000
A7: Dean of FED | B7: 10000
A8: Dean of FST | B8: 10000
A9: Dean of FCOM | B9: 10000
A10: Dean of FSW | B10: 10000
A11: Dean of FPHHN | B11: 10000
A12: Dean of students | B12: 10000
A13: Academic Registrar | B13: 10000
A14: Academic secretaries FCRS | B14: 10000
... A46: Driver 2 | B46: 3000
B47: =SUM(B2:B46) -> 466000

Sheet Responsability allowance
A1: Responsibility allowance
A2: Dean of FCRS | B2: 200000
A3: Dean of FED | B3: 200000
A4: Dean of FST | B4: 200000
A5: Dean of FCOM | B5: 200000
A6: Dean of FSW | B6: 200000
A7: Dean of FPHHN | B7: 200000
A8: Academic secretaries FCRS | B8: 150000
A9: Academic secretaries FED | B9: 150000
A10: Academic secretaries FST | B10: 150000
A11: Academic secretaries FCOM | B11: 150000
A12: Academic secretaries FSW | B12: 150000
A13: Academic secretaries FPHHN | B13: 150000
... A23: HOD HN&PH | B23: 150000
B24: =SUM(B2:B23) -> 3600000

Sheet Sheet5
A1: Panel fees
C2: Supervisor | D2: Panel members
A3: Number of graduates | B3: 260 | C3: =B3*15000 -> 3900000 | D3: =B3*2*10000 -> 5200000 | E3: =C3+D3 -> 9100000

Sheet Part-time staff cost
B4: Part-time
A5: FCRS | B5: 3574075
A6: FSW | B6: 3522960
A7: FST | B7: 2253360
A8: FPHHN | B8: 2419200
A9: FCOM | B9: 4094880
A10: FED | B10: 73274100
B11: 89138575
A12: 0.083 | B12: =B11*A12 -> 7398501.7
B13: =B11+B12 -> 96537077

Sheet STAFF COST DETAILS
A1: Proposed Salary structure | B1: Proposed new structure | C1: Existing structure | D1: Difference
A2: Senior Lecturer | B2: 1081433.7 | C2: 1029936.9 | D2: =B2-C2 -> 51496.843
A3: Lecturer | B3: 772600.95 | C3: 735810.43 | D3: =B3-C3 -> 36790.521
A4: Ass Lecturer | B4: 617402.25 | C4: 588002.14 | D4: =B4-C4 -> 29400.107
A5: Tutorial Ass | B5: 517495.5 | C5: 492853 | D5: =B5-C5 -> 24642.5
A7: This change of increase of 5% of basic salary will have overall impact which the following:
A8: Total staff cost will increase Monthly by:
A9: Academic staff | B9: =--893988.285714287 -> 893988.29
A10: Administratif staff | B10: 653976.13
A11: Total Monthly Increase | B11: =SUM(B9:B10) -> 1547964.4 | C11: 1547964.4
A12: Total annual increase in staff | B12: =B11*12 -> 18575573 | C12: 18575573
