Workbook

Sheet BUDGET 2024-2025
B8: Financial Budget for Academic year 2024-2025
B9: September | C9: October | D9: November | E9: December | F9: January | G9: February | H9: March | I9: April | J9: May | K9: June | L9: July | M9: August | N9: GENERAL TOTAL
B10: TOTAL | C10: TOTAL | D10: TOTAL | E10: TOTAL | F10: TOTAL | G10: TOTAL | H10: TOTAL | I10: TOTAL | J10: TOTAL | K10: TOTAL | L10: TOTAL | M10: TOTAL | N10: TOTAL
A11: Budgeted Number of Students | N11: ='INCOME DETAILS'!Q121 -> 3997
A12: Revenue
A13: Tuition Fees
A14: Faculty of Catechesis and Religious Sciences | B14: =N14/12 -> 6041666.7 | C14: 6041666.7 | D14: 6041666.7 | E14: 6041666.7 | F14: 6041666.7 | G14: 6041666.7 | H14: 6041666.7 | I14: 6041666.7 | J14: 6041666.7 | K14: 6041666.7 | L14: 6041666.7 | M14: 6041666.7 | N14: ='INCOME DETAILS'!AB104 -> 72500000
A15: Faculty of Commerce | B15: =N15/12 -> 10250000 | C15: 12437500 | D15: 12437500 | E15: 12437500 | F15: 12437500 | G15: 12437500 | H15: 12437500 | I15: 12437500 | J15: 12437500 | K15: 12437500 | L15: 12437500 | M15: 12437500 | N15: ='INCOME DETAILS'!AB112 -> 123000000
A16: Faculty of Education -under graduates | B16: =N16/12 -> 41477500 | C16: 45802500 | D16: 45802500 | E16: 45802500 | F16: 45802500 | G16: 45802500 | H16: 45802500 | I16: 45802500 | J16: 45802500 | K16: 45802500 | L16: 45802500 | M16: 45802500 | N16: ='INCOME DETAILS'!AB62 -> 497730000
A17: Faculty of Education -PGD- Taba campus-Kibungo Learning Center | B17: =N17/12 -> 5160750 | C17: 7155750 | D17: 7155750 | E17: 7155750 | F17: 7155750 | G17: 7155750 | H17: 7155750 | I17: 7155750 | J17: 7155750 | K17: 7155750 | L17: 7155750 | M17: 7155750 | N17: ='INCOME DETAILS'!AB117 -> 61929000
A18: Faculty of Public Health and Human Nutrition | B18: =N18/12 -> 3428333.3 | C18: 9997083.3 | D18: 9997083.3 | E18: 9997083.3 | F18: 9997083.3 | G18: 9997083.3 | H18: 9997083.3 | I18: 9997083.3 | J18: 9997083.3 | K18: 9997083.3 | L18: 9997083.3 | M18: 9997083.3 | N18: ='INCOME DETAILS'!AB96 -> 41140000
A19: Faculty of Science and Technology | B19: =N19/12 -> 10931250 | C19: 12264583 | D19: 12264583 | E19: 12264583 | F19: 12264583 | G19: 12264583 | H19: 12264583 | I19: 12264583 | J19: 12264583 | K19: 12264583 | L19: 12264583 | M19: 12264583 | N19: ='INCOME DETAILS'!AB28 -> 131175000
A20: Faculty of Social Work | B20: =N20/12 -> 2770833.3 | C20: 2770833.3 | D20: 2770833.3 | E20: 2770833.3 | F20: 2770833.3 | G20: 2770833.3 | H20: 2770833.3 | I20: 2770833.3 | J20: 2770833.3 | K20: 2770833.3 | L20: 2770833.3 | M20: 2770833.3 | N20: ='INCOME DETAILS'!AB36 -> 33250000
A21: Expected New Masters Program fees | K21: =N21/3 -> 0 | L21: 0 | M21: 0 | N21: ='INCOME DETAILS'!AB120 -> 0
A22: Ministry of health sponsored student
A23: Existing Sponsored | B23: =N23/12 -> 23065417 | C23: 23065417 | D23: 23065417 | E23: 23065417 | F23: 23065417 | G23: 23065417 | H23: 23065417 | I23: 23065417 | J23: 23065417 | K23: 23065417 | L23: 23065417 | M23: 23065417 | N23: 276785000 | O23: =N23+N24+N25+N26-N24 -> 7.1875399e+08
A24: Projected Sponsored | K24: =N24/3 -> 24625000 | L24: 24625000 | M24: 24625000 | N24: ='INCOME DETAILS'!S124 -> 73875000
A25: Chancen Student Tuition fees | B25: =N25/12 -> 32324778 | C25: 32324778 | D25: 32324778 | E25: 32324778 | F25: 32324778 | G25: 32324778 | H25: 32324778 | I25: 32324778 | J25: 32324778 | K25: 32324778 | L25: 32324778 | M25: 32324778 | N25: ='INCOME DETAILS'!F133 -> 3.8789733e+08
A26: YWCA | F26: =N26/9 -> 6007962.2 | G26: 6007962.2 | H26: 6007962.2 | I26: 6007962.2 | J26: 6007962.2 | K26: 6007962.2 | L26: 6007962.2 | M26: 6007962.2 | N26: ='INCOME DETAILS'!E140 -> 54071660
A27: Total Tuition fees | B27: =SUM(B14:B26) -> 1.3545053e+08 | C27: =SUM(C14:C26) -> 1.5186011e+08 | D27: =SUM(D14:D26) -> 1.5186011e+08 | E27: =SUM(E14:E26) -> 1.5186011e+08 | F27: =SUM(F14:F26) -> 1.5786807e+08 | G27: =SUM(G14:G26) -> 1.5786807e+08 | H27: =SUM(H14:H26) -> 1.5786807e+08 | I27: =SUM(I14:I26) -> 1.5786807e+08 | ... N27: =SUM(N14:N26) -> 1.753353e+09
A28: Application fees | B28: =N28/12 -> 703333.33 | C28: 930416.67 | D28: 930416.67 | E28: 930416.67 | F28: 930416.67 | G28: 930416.67 | H28: 930416.67 | I28: 930416.67 | J28: 930416.67 | K28: 930416.67 | L28: 930416.67 | M28: 930416.67 | N28: ='INCOME DETAILS'!AD121 -> 8440000
A29: Internship fees | B29: =N29/12 -> 3187500 | C29: 2870833.3 | D29: 2870833.3 | E29: 2870833.3 | F29: 2870833.3 | G29: 2870833.3 | H29: 2870833.3 | I29: 2870833.3 | J29: 2870833.3 | K29: 2870833.3 | L29: 2870833.3 | M29: 2870833.3 | N29: ='INCOME DETAILS'!AE121 -> 38250000
A30: Research supervision fees | B30: =N30/12 -> 3837500 | C30: 3837500 | D30: 3837500 | E30: 3837500 | F30: 3837500 | G30: 3837500 | H30: 3837500 | I30: 3837500 | J30: 3837500 | K30: 3837500 | L30: 3837500 | M30: 3837500 | N30: ='INCOME DETAILS'!AF121 -> 46050000
A31: Graduation fees | J31: =N31 -> 13000000 | N31: =260*50000 -> 13000000
A32: Fines | B32: =N32/12 -> 50820 | C32: 50820 | D32: 50820 | E32: 50820 | F32: 50820 | G32: 50820 | H32: 50820 | I32: 50820 | J32: 50820 | K32: 50820 | L32: 50820 | M32: 50820 | N32: 609840
A33: Retake fees | B33: =N33/12 -> 33333.333 | C33: 33333.333 | D33: 33333.333 | E33: 33333.333 | F33: 33333.333 | G33: 33333.333 | H33: 33333.333 | I33: 33333.333 | J33: 33333.333 | K33: 33333.333 | L33: 33333.333 | M33: 33333.333 | N33: 400000
A34: Academic documents fees | B34: =N34/12 -> 232466.67 | C34: 232466.67 | D34: 232466.67 | E34: 232466.67 | F34: 232466.67 | G34: 232466.67 | H34: 232466.67 | I34: 232466.67 | J34: 232466.67 | K34: 232466.67 | L34: 232466.67 | M34: 232466.67 | N34: 2789600
A35: Total academic cost | B35: =SUM(B27:B34) -> 1.4349548e+08 | C35: =SUM(C27:C34) -> 1.5981548e+08 | D35: =SUM(D27:D34) -> 1.5981548e+08 | E35: =SUM(E27:E34) -> 1.5981548e+08 | F35: =SUM(F27:F34) -> 1.6582344e+08 | G35: =SUM(G27:G34) -> 1.6582344e+08 | H35: =SUM(H27:H34) -> 1.6582344e+08 | I35: =SUM(I27:I34) -> 1.6582344e+08 | ... N35: =SUM(N27:N34) -> 1.8628924e+09
A37: Other Income
A38: Accomodation fee | B38: =N38/12 -> 1309000 | C38: 109083.33 | D38: 109083.33 | E38: 109083.33 | F38: 109083.33 | G38: 109083.33 | H38: 109083.33 | I38: 109083.33 | J38: 109083.33 | K38: 109083.33 | L38: 109083.33 | M38: 109083.33 | N38: =187*7000*12 -> 15708000
A39: Other Income(Different IURA Projects) | F39: =N39/8 -> 12500000 | G39: 12500000 | H39: 12500000 | I39: 12500000 | J39: 12500000 | K39: 12500000 | L39: 12500000 | M39: 12500000 | N39: 100000000
A40: Total Income | B40: =B38+B39 -> 1309000 | C40: =C38+C39 -> 109083.33 | D40: =D38+D39 -> 109083.33 | E40: =E38+E39 -> 109083.33 | F40: =F38+F39 -> 12609083 | G40: =G38+G39 -> 12609083 | H40: =H38+H39 -> 12609083 | I40: =I38+I39 -> 12609083 | ... N40: =N38+N39 -> 115708000
A41: TOTAL REVENUE(A) | B41: =B40+B35 -> 1.4480448e+08 | C41: =C40+C35 -> 1.5992456e+08 | D41: =D40+D35 -> 1.5992456e+08 | E41: =E40+E35 -> 1.5992456e+08 | F41: =F40+F35 -> 1.7843253e+08 | G41: =G40+G35 -> 1.7843253e+08 | H41: =H40+H35 -> 1.7843253e+08 | I41: =I40+I35 -> 1.7843253e+08 | ... N41: =N40+N35 -> 1.9786004e+09
A42: OPERATING EXPENSES
A43: Staff Cost
A44: Full timeTeaching staff | B44: 32407582 | C44: 32407582 | D44: 32407582 | E44: 32407582 | F44: 32407582 | G44: 32407582 | H44: 32407582 | I44: 32407582 | J44: 32407582 | K44: 36319385 | L44: 36319385 | M44: 36319385 | N44: =SUM(B44:M44) -> 4.0062639e+08
A45: Part time teaching staff | B45: ='Part-time staff cost'!B13/12 -> 8044756.4 | C45: =B45 -> 8044756.4 | D45: =C45 -> 8044756.4 | E45: =D45 -> 8044756.4 | F45: =E45 -> 8044756.4 | G45: =F45 -> 8044756.4 | H45: =G45 -> 8044756.4 | I45: =H45 -> 8044756.4 | J45: =I45 -> 8044756.4 | ... M45: =L45 -> 8044756.4 | N45: =SUM(B45:M45) -> 96537077
A46: Administrative + Support staff | B46: 14887169 | C46: 14887169 | D46: 14887169 | E46: 14887169 | F46: 14887169 | G46: 14887169 | H46: 14887169 | I46: 14887169 | J46: 14887169 | K46: 17500450 | L46: 17500450 | M46: 17500450 | N46: =SUM(B46:M46) -> 1.8648587e+08
A47: Other payment(Consultancy fees) | B47: 2851511.5 | C47: 2851511.5 | D47: 2851511.5 | E47: 2851511.5 | F47: 2851511.5 | G47: 2851511.5 | H47: 2851511.5 | I47: 2851511.5 | J47: 2851511.5 | K47: 2851511.5 | L47: 2851511.5 | M47: 2851511.5 | N47: =SUM(B47:M47) -> 34218138
A48: CPA staff | B48: 1200000 | C48: 1200000 | D48: 1200000 | E48: 1200000 | F48: 1200000 | G48: 1200000 | H48: 1200000 | I48: 1200000 | J48: 1200000 | K48: 1200000 | L48: 1200000 | M48: 1200000 | N48: =SUM(B48:M48) -> 14400000
...

Sheet Execution of the budget
A1: BUDGET EXECUTION FOR ACADEMIC YEAR 2024-2025
N3: Number of students | O3: % Increase
A4: Number of student at start of 2024-2025 | N4: 2492
A5: Number of student at end of 2024-2025 | N5: 3442
A6: Increase in number of student at year end | B6: Financial Budget for Academic year 2024-2025 | N6: =N5-N4 -> 950 | O6: =N6/N4 -> 0.3812199
A8: PARTICULARS | B8: September | C8: October | D8: November | E8: December | F8: January | G8: February | H8: March | I8: April | J8: May | K8: June | L8: July | M8: August | N8: BUDGET 2024-2025 | O8: BUDGET EXECUTION 2024-2025 | P8: Variance | Q8: % of realisation
B9: TOTAL | C9: TOTAL | D9: TOTAL | E9: TOTAL | F9: TOTAL | G9: TOTAL | H9: TOTAL | I9: TOTAL | J9: TOTAL | K9: TOTAL | L9: TOTAL | M9: TOTAL | N9: TOTAL | O9: TOTAL
A10: Budgeted Number of Students | N10: ='INCOME DETAILS'!Q121 -> 3997 | O10: 3442 | P10: =O10-N10 -> -555 | Q10: =O10/N10 -> 0.86114586
A11: Revenue
A12: Tuition Fees
A13: Faculty of Catechesis and Religious Sciences | B13: =N13/12 -> 6041666.7 | C13: 6041666.7 | D13: 6041666.7 | E13: 6041666.7 | F13: 6041666.7 | G13: 6041666.7 | H13: 6041666.7 | I13: 6041666.7 | J13: 6041666.7 | K13: 6041666.7 | L13: 6041666.7 | M13: 6041666.7 | N13: ='INCOME DETAILS'!AB104 -> 72500000
A14: Faculty of Commerce | B14: =N14/12 -> 10250000 | C14: 12437500 | D14: 12437500 | E14: 12437500 | F14: 12437500 | G14: 12437500 | H14: 12437500 | I14: 12437500 | J14: 12437500 | K14: 12437500 | L14: 12437500 | M14: 12437500 | N14: ='INCOME DETAILS'!AB112 -> 123000000
A15: Faculty of Education -under graduates | B15: =N15/12 -> 41477500 | C15: 45802500 | D15: 45802500 | E15: 45802500 | F15: 45802500 | G15: 45802500 | H15: 45802500 | I15: 45802500 | J15: 45802500 | K15: 45802500 | L15: 45802500 | M15: 45802500 | N15: ='INCOME DETAILS'!AB62 -> 497730000
A16: Faculty of Education -PGD- Taba campus-Kibungo Learning Center | B16: =N16/12 -> 5160750 | C16: 7155750 | D16: 7155750 | E16: 7155750 | F16: 7155750 | G16: 7155750 | H16: 7155750 | I16: 7155750 | J16: 7155750 | K16: 7155750 | L16: 7155750 | M16: 7155750 | N16: ='INCOME DETAILS'!AB117 -> 61929000
A17: Faculty of Public Health and Human Nutrition | B17: =N17/12 -> 3428333.3 | C17: 9997083.3 | D17: 9997083.3 | E17: 9997083.3 | F17: 9997083.3 | G17: 9997083.3 | H17: 9997083.3 | I17: 9997083.3 | J17: 9997083.3 | K17: 9997083.3 | L17: 9997083.3 | M17: 9997083.3 | N17: ='INCOME DETAILS'!AB96 -> 41140000
A18: Faculty of Science and Technology | B18: =N18/12 -> 10931250 | C18: 12264583 | D18: 12264583 | E18: 12264583 | F18: 12264583 | G18: 12264583 | H18: 12264583 | I18: 12264583 | J18: 12264583 | K18: 12264583 | L18: 12264583 | M18: 12264583 | N18: ='INCOME DETAILS'!AB28 -> 131175000
A19: Faculty of Social Work | B19: =N19/12 -> 2770833.3 | C19: 2770833.3 | D19: 2770833.3 | E19: 2770833.3 | F19: 2770833.3 | G19: 2770833.3 | H19: 2770833.3 | I19: 2770833.3 | J19: 2770833.3 | K19: 2770833.3 | L19: 2770833.3 | M19: 2770833.3 | N19: ='INCOME DETAILS'!AB36 -> 33250000
A20: Expected New Masters Program fees | K20: =N20/3 -> 0 | L20: 0 | M20: 0 | N20: ='INCOME DETAILS'!AB120 -> 0
A21: Ministry of health sponsored student
A22: Existing Sponsored | B22: =N22/12 -> 23065417 | C22: 23065417 | D22: 23065417 | E22: 23065417 | F22: 23065417 | G22: 23065417 | H22: 23065417 | I22: 23065417 | J22: 23065417 | K22: 23065417 | L22: 23065417 | M22: 23065417 | N22: 276785000
A23: Projected Sponsored | K23: =N23/3 -> 24625000 | L23: 24625000 | M23: 24625000 | N23: ='INCOME DETAILS'!S124 -> 73875000
A24: Chancen Student Tuition fees | B24: =N24/12 -> 32324778 | C24: 32324778 | D24: 32324778 | E24: 32324778 | F24: 32324778 | G24: 32324778 | H24: 32324778 | I24: 32324778 | J24: 32324778 | K24: 32324778 | L24: 32324778 | M24: 32324778 | N24: ='INCOME DETAILS'!F133 -> 3.8789733e+08
A25: YWCA | F25: =N25/9 -> 6007962.2 | G25: 6007962.2 | H25: 6007962.2 | I25: 6007962.2 | J25: 6007962.2 | K25: 6007962.2 | L25: 6007962.2 | M25: 6007962.2 | N25: ='INCOME DETAILS'!E140 -> 54071660
A26: Income fromTuition fees | B26: =SUM(B13:B25) -> 1.3545053e+08 | C26: =SUM(C13:C25) -> 1.5186011e+08 | D26: =SUM(D13:D25) -> 1.5186011e+08 | E26: =SUM(E13:E25) -> 1.5186011e+08 | F26: =SUM(F13:F25) -> 1.5786807e+08 | G26: =SUM(G13:G25) -> 1.5786807e+08 | H26: =SUM(H13:H25) -> 1.5786807e+08 | I26: =SUM(I13:I25) -> 1.5786807e+08 | ... N26: =SUM(N13:N25) -> 1.753353e+09 | O26: 1088767000 | P26: =O26-N26 -> -6.6458599e+08 | Q26: =O26/N26 -> 0.62096281
A27: Application fees | B27: =N27/12 -> 703333.33 | C27: 930416.67 | D27: 930416.67 | E27: 930416.67 | F27: 930416.67 | G27: 930416.67 | H27: 930416.67 | I27: 930416.67 | J27: 930416.67 | K27: 930416.67 | L27: 930416.67 | M27: 930416.67 | N27: ='INCOME DETAILS'!AD121 -> 8440000 | O27: 9970000 | P27: =O27-N27 -> 1530000 | Q27: =O27/N27 -> 1.1812796
A28: Internship fees | B28: =N28/12 -> 3187500 | C28: 2870833.3 | D28: 2870833.3 | E28: 2870833.3 | F28: 2870833.3 | G28: 2870833.3 | H28: 2870833.3 | I28: 2870833.3 | J28: 2870833.3 | K28: 2870833.3 | L28: 2870833.3 | M28: 2870833.3 | N28: ='INCOME DETAILS'!AE121 -> 38250000 | O28: 33980000 | P28: =O28-N28 -> -4270000 | Q28: =O28/N28 -> 0.88836601
A29: Research supervision fees | B29: =N29/12 -> 3837500 | C29: 3837500 | D29: 3837500 | E29: 3837500 | F29: 3837500 | G29: 3837500 | H29: 3837500 | I29: 3837500 | J29: 3837500 | K29: 3837500 | L29: 3837500 | M29: 3837500 | N29: ='INCOME DETAILS'!AF121 -> 46050000 | O29: 63450000 | P29: =O29-N29 -> 17400000 | Q29: =O29/N29 -> 1.3778502
A30: Graduation fees | J30: =N30 -> 13000000 | N30: =260*50000 -> 13000000 | O30: 12730000 | P30: =O30-N30 -> -270000 | Q30: =O30/N30 -> 0.97923077
A31: Fines | B31: =N31/12 -> 50820 | C31: 50820 | D31: 50820 | E31: 50820 | F31: 50820 | G31: 50820 | H31: 50820 | I31: 50820 | J31: 50820 | K31: 50820 | L31: 50820 | M31: 50820 | N31: 609840 | O31: 0 | P31: =O31-N31 -> -609840 | Q31: =O31/N31 -> 0
A32: Retake fees | B32: =N32/12 -> 33333.333 | C32: 33333.333 | D32: 33333.333 | E32: 33333.333 | F32: 33333.333 | G32: 33333.333 | H32: 33333.333 | I32: 33333.333 | J32: 33333.333 | K32: 33333.333 | L32: 33333.333 | M32: 33333.333 | N32: 400000 | O32: 0 | P32: =O32-N32 -> -400000 | Q32: =O32/N32 -> 0
A33: Academic documents fees | B33: =N33/12 -> 232466.67 | C33: 232466.67 | D33: 232466.67 | E33: 232466.67 | F33: 232466.67 | G33: 232466.67 | H33: 232466.67 | I33: 232466.67 | J33: 232466.67 | K33: 232466.67 | L33: 232466.67 | M33: 232466.67 | N33: 2789600 | O33: 1905000 | P33: =O33-N33 -> -884600 | Q33: =O33/N33 -> 0.6828936
A34: Total academic cost | B34: =SUM(B26:B33) -> 1.4349548e+08 | C34: =SUM(C26:C33) -> 1.5981548e+08 | D34: =SUM(D26:D33) -> 1.5981548e+08 | E34: =SUM(E26:E33) -> 1.5981548e+08 | F34: =SUM(F26:F33) -> 1.6582344e+08 | G34: =SUM(G26:G33) -> 1.6582344e+08 | H34: =SUM(H26:H33) -> 1.6582344e+08 | I34: =SUM(I26:I33) -> 1.6582344e+08 | ... O34: =SUM(O26:O33) -> 1210802000 | Q34: =O34/N34 -> 0.64995809
A35: Other Income
A36: Accomodation fee | B36: =N36/12 -> 1309000 | C36: 109083.33 | D36: 109083.33 | E36: 109083.33 | F36: 109083.33 | G36: 109083.33 | H36: 109083.33 | I36: 109083.33 | J36: 109083.33 | K36: 109083.33 | L36: 109083.33 | M36: 109083.33 | N36: =187*7000*12 -> 15708000 | O36: 7345500 | P36: =O36-N36 -> -8362500 | Q36: =O36/N36 -> 0.46762796
A37: Other Income(Different IURA Projects) | F37: =N37/8 -> 12500000 | G37: 12500000 | H37: 12500000 | I37: 12500000 | J37: 12500000 | K37: 12500000 | L37: 12500000 | M37: 12500000 | N37: 100000000 | O37: 1.4241223e+08 | P37: =O37-N37 -> 42412233 | Q37: =O37/N37 -> 1.4241223
A38: Total Other Income | B38: =B36+B37 -> 1309000 | C38: =C36+C37 -> 109083.33 | D38: =D36+D37 -> 109083.33 | E38: =E36+E37 -> 109083.33 | F38: =F36+F37 -> 12609083 | G38: =G36+G37 -> 12609083 | H38: =H36+H37 -> 12609083 | I38: =I36+I37 -> 12609083 | ... O38: =O36+O37 -> 1.4975773e+08 | P38: =N38-O38 -> -34049733 | Q38: =O38/N38 -> 1.2942729
A39: TOTAL REVENUE(A) | B39: =B38+B34 -> 1.4480448e+08 | C39: =C38+C34 -> 1.5992456e+08 | D39: =D38+D34 -> 1.5992456e+08 | E39: =E38+E34 -> 1.5992456e+08 | F39: =F38+F34 -> 1.7843253e+08 | G39: =G38+G34 -> 1.7843253e+08 | H39: =H38+H34 -> 1.7843253e+08 | I39: =I38+I34 -> 1.7843253e+08 | ... O39: =O38+O34 -> 1.3605597e+09 | P39: =N39-O39 -> 6.180407e+08 | Q39: =O39/N39 -> 0.68763744
A40: OPERATING EXPENSES
A41: Staff Cost
A42: Full timeTeaching staff | B42: 32407582 | C42: 32407582 | D42: 32407582 | E42: 32407582 | F42: 32407582 | G42: 32407582 | H42: 32407582 | I42: 32407582 | J42: 32407582 | K42: 36319385 | L42: 36319385 | M42: 36319385 | N42: =SUM(B42:M42) -> 4.0062639e+08 | O42: 3.785134e+08 | P42: =O42-N42 -> -22112990 | Q42: =O42/N42 -> 0.94480396
...

Sheet INCOME DETAILS
C1: Current Student | G1: Projected New student
G2: September 2024 Intake | J2: March 2025 Intake | M2: June 2025 Intake
C3: Day program | D3: Weekend Program | E3: Holiday Program | F3: Total Existing | G3: Day program | H3: Weekend Program | I3: Holiday Program | J3: Day program | K3: Weekend Program | L3: Holiday Program | M3: Day program | N3: Weekend Program | O3: Holiday Program | P3: Total Projected | Q3: Total Student Budgeted 2024-2025 | R3: Sponsored Student | AB3: Tuition fees | AC3: Registration fees+Technology fees | AD3: Application fees | AE3: Internship fees | AF3: Final project fees | AG3: Total
R4: Minisante | T4: Chancen | V4: YWCA | W4: Private student | X4: Existing private student | Y4: Projected Private
R5: Existing | S5: Projected | T5: Existing | U5: Projected | V5: Projected | Y5: Sept int | Z5: March In | AA5: June int
B6: 1.Faculty of science and technology
B7: 1.1 Department Biomedical Laboratory science
B8: L8 S1&2 | C8: 22 | D8: 0 | E8: 0 | F8: =SUM(C8:E8) -> 22 | H8: 0 | I8: 0 | J8: 15 | K8: 0 | L8: 0 | N8: 0 | O8: 0 | P8: =SUM(G8:O8) -> 15 | Q8: =F8+P8 -> 37 | R8: 14 | U8: 10 | V8: 5 | W8: =Q8-SUM(R8:V8) -> 8 | X8: =F8-R8-T8 -> 8 | AB8: =((X8*600000)+(Y8*600000)+(Z8*450000)+(AA8*300000)) -> 4800000 | AC8: =W8*33000 -> 264000 | AD8: =W8*5000 -> 40000 | AG8: =SUM(AB8:AD8) -> 5104000
B9: L8 S3&4 | C9: 26 | D9: 0 | E9: 0 | F9: =SUM(C9:E9) -> 26 | G9: 0 | H9: 0 | I9: 0 | J9: 0 | K9: 0 | L9: 0 | M9: 0 | N9: 0 | O9: 0 | P9: =SUM(G9:O9) -> 0 | Q9: =F9+P9 -> 26 | R9: 0 | W9: =Q9-SUM(R9:V9) -> 26 | X9: =F9-R9-T9 -> 26 | AB9: =((X9*600000)+(Y9*600000)+(Z9*450000)+(AA9*300000)) -> 15600000 | AC9: =W9*33000 -> 858000 | AE9: =(X9-Y9-Z9-AA9)*160000 -> 4160000 | AG9: =SUM(AB9:AD9) -> 16458000
B10: L8 S5&6 | C10: 76 | D10: 0 | E10: 0 | F10: =SUM(C10:E10) -> 76 | G10: 10 | H10: 0 | I10: 0 | K10: 0 | L10: 0 | M10: 20 | N10: 0 | O10: 0 | P10: =SUM(G10:O10) -> 30 | Q10: =F10+P10 -> 106 | R10: 0 | U10: 30 | W10: =Q10-SUM(R10:V10) -> 76 | X10: =F10-R10-T10 -> 76 | Y10: 0 | AA10: 0 | AB10: =((X10*600000)+(Y10*600000)+(Z10*450000)+(AA10*300000)) -> 45600000 | AC10: =W10*33000 -> 2508000 | AE10: =(X10-Y10-Z10-AA10)*160000 -> 12160000 | AG10: =SUM(AB10:AD10) -> 48108000
B11: L8 S7&8 | C11: 18 | D11: 0 | E11: 0 | F11: =SUM(C11:E11) -> 18 | G11: 0 | H11: 0 | I11: 0 | J11: 0 | K11: 0 | L11: 0 | M11: 0 | N11: 0 | O11: 0 | P11: =SUM(G11:O11) -> 0 | Q11: =F11+P11 -> 18 | R11: 0 | W11: =Q11-SUM(R11:V11) -> 18 | X11: =F11-R11-T11 -> 18 | AB11: =((X11*600000)+(Y11*600000)+(Z11*450000)+(AA11*300000)) -> 10800000 | AC11: =W11*33000 -> 594000 | AE11: =(X11-Y11-Z11-AA11)*160000 -> 2880000 | AG11: =SUM(AB11:AD11) -> 11394000
B12: Graduands | D12: 0 | E12: 0 | F12: =SUM(C12:E12) -> 0 | G12: 0 | H12: 0 | I12: 0 | J12: 0 | K12: 0 | L12: 0 | M12: 0 | N12: 0 | O12: 0 | P12: =SUM(G12:O12) -> 0 | Q12: =F12+P12 -> 0 | X12: =F12-R12-T12 -> 0
B13: Total students in BLS | F13: =SUM(F8:F12) -> 142 | G13: =SUM(G8:G12) -> 10 | H13: =SUM(H8:H12) -> 0 | I13: =SUM(I8:I12) -> 0 | J13: =SUM(J8:J12) -> 15 | K13: =SUM(K8:K12) -> 0 | L13: =SUM(L8:L12) -> 0 | M13: =SUM(M8:M12) -> 20 | ... AG13: =SUM(AG8:AG12) -> 81064000
B14: 1.2 Department of computer science
B15: L8 S1&2 | C15: =35+4 -> 39 | D15: 23 | F15: =SUM(C15:E15) -> 62 | G15: 10 | H15: 20 | I15: 0 | J15: 30 | K15: 10 | L15: 0 | M15: 10 | N15: 20 | O15: 0 | P15: =SUM(G15:O15) -> 100 | Q15: =F15+P15 -> 162 | T15: =21 -> 21 | U15: 50 | V15: 40 | W15: =Q15-SUM(R15:V15) -> 51 | X15: =F15-R15-T15 -> 41 | Z15: 10 | AB15: =((X15*375000)+(Y15*375000)+(Z15*250000)+(AA15*125000)) -> 17875000 | AC15: =W15*33000 -> 1683000 | AD15: =W15*5000 -> 255000 | AG15: =SUM(AB15:AD15) -> 19813000
B16: L8 S3&4 | C16: 63 | F16: =SUM(C16:E16) -> 63 | G16: 0 | H16: 0 | I16: 0 | J16: 0 | K16: 0 | L16: 0 | M16: 0 | N16: 0 | O16: 0 | P16: =SUM(G16:O16) -> 0 | Q16: =F16+P16 -> 63 | T16: 66 | W16: =Q16-SUM(R16:V16) -> -3 | X16: =F16-R16-T16 -> -3 | AG16: =SUM(AB16:AD16) -> 0
B17: L8 S5&6 | C17: 8 | D17: 20 | F17: =SUM(C17:E17) -> 28 | G17: 0 | H17: 10 | I17: 0 | J17: 0 | L17: 0 | M17: 0 | N17: 10 | O17: 0 | P17: =SUM(G17:O17) -> 20 | Q17: =F17+P17 -> 48 | W17: =Q17-SUM(R17:V17) -> 48 | X17: =F17-R17-T17 -> 28 | Z17: 10 | AA17: 10 | AB17: =((X17*375000)+(Y17*375000)+(Z17*250000)+(AA17*125000)) -> 14250000 | AC17: =W17*33000 -> 1584000 | AG17: =SUM(AB17:AD17) -> 15834000
B18: L8 S7&8 | C18: 17 | D18: 19 | F18: =SUM(C18:E18) -> 36 | G18: 0 | H18: 0 | I18: 0 | J18: 0 | K18: 0 | L18: 0 | M18: 0 | N18: 0 | O18: 0 | P18: =SUM(G18:O18) -> 0 | Q18: =F18+P18 -> 36 | W18: =Q18-SUM(R18:V18) -> 36 | X18: =F18-R18-T18 -> 36 | AB18: =((X18*375000)+(Y18*375000)+(Z18*250000)+(AA18*125000)) -> 13500000 | AC18: =W18*33000 -> 1188000 | AE18: =W18*30000 -> 1080000 | AF18: =W18*150000 -> 5400000 | AG18: =SUM(AB18:AD18) -> 14688000
B19: Graduands | F19: =SUM(C19:E19) -> 0 | G19: 0 | H19: 0 | I19: 0 | J19: 0 | K19: 0 | L19: 0 | M19: 0 | N19: 0 | O19: 0 | P19: =SUM(G19:O19) -> 0 | Q19: =F19+P19 -> 0 | X19: =F19-R19-T19 -> 0 | AB19: =((X19*375000)+(Y19*375000)+(Z19*250000)+(AA19*125000)) -> 0 | AC19: =W19*33000 -> 0
B20: Total Students in CS | C20: =SUM(C15:C19) -> 127 | D20: =SUM(D15:D19) -> 62 | F20: =SUM(F15:F19) -> 189 | G20: =SUM(G15:G19) -> 10 | H20: =SUM(H15:H19) -> 30 | I20: =SUM(I15:I19) -> 0 | J20: =SUM(J15:J19) -> 30 | K20: =SUM(K15:K19) -> 10 | L20: =SUM(L15:L19) -> 0 | M20: =SUM(M15:M19) -> 10 | ... O20: =SUM(O15:O19) -> 0 | Q20: =SUM(Q15:Q19) -> 309 | R20: =SUM(R15:R19) -> 0 | S20: =SUM(S15:S19) -> 0 | T20: =SUM(T15:T19) -> 87 | U20: =SUM(U15:U19) -> 50 | V20: =SUM(V15:V19) -> 40 | W20: =SUM(W15:W19) -> 132 | X20: =SUM(X15:X19) -> 102 | ... AG20: =SUM(AG15:AG19) -> 50335000
B21: 1.3 Food processing Department
B22: L8 S1&2 | C22: 0 | D22: 0 | E22: 0 | F22: =SUM(C22:E22) -> 0 | G22: 0 | H22: 0 | I22: 0 | J22: 0 | K22: 0 | L22: 0 | M22: 50 | N22: 20 | P22: =SUM(G22:O22) -> 70 | Q22: =F22+P22 -> 70 | W22: =Q22-SUM(R22:V22) -> 70 | X22: =F22-R22-T22 -> 0 | AA22: 70 | AB22: =((X22*375000)+(Y22*375000)+(Z22*250000)+(AA22*125000)) -> 8750000 | AC22: =W22*33000 -> 2310000 | AD22: =W22*5000 -> 350000 | AG22: =SUM(AB22:AD22) -> 11410000
B23: L8 S3&4 | C23: 0 | D23: 0 | E23: 0 | F23: =SUM(C23:E23) -> 0 | G23: 0 | H23: 0 | I23: 0 | J23: 0 | K23: 0 | L23: 0 | M23: 0 | N23: 0 | O23: 0 | P23: =SUM(G23:O23) -> 0 | Q23: =F23+P23 -> 0 | W23: =Q23-SUM(R23:V23) -> 0 | X23: =F23-R23-T23 -> 0 | AC23: =W23*33000 -> 0 | AD23: =W23*5000 -> 0 | AE23: 0 | AF23: 0 | AG23: =SUM(AB23:AD23) -> 0
B24: L8 S5&6 | C24: 0 | D24: 0 | E24: 0 | F24: =SUM(C24:E24) -> 0 | G24: 0 | H24: 0 | I24: 0 | J24: 0 | K24: 0 | L24: 0 | M24: 0 | N24: 0 | O24: 0 | P24: =SUM(G24:O24) -> 0 | Q24: =F24+P24 -> 0 | W24: =Q24-SUM(R24:V24) -> 0 | X24: =F24-R24-T24 -> 0 | AC24: =W24*33000 -> 0 | AD24: =W24*5000 -> 0 | AE24: 0 | AF24: 0 | AG24: =SUM(AB24:AD24) -> 0
B25: L8 S7&8 | C25: 0 | D25: 0 | E25: 0 | F25: =SUM(C25:E25) -> 0 | G25: 0 | H25: 0 | I25: 0 | J25: 0 | K25: 0 | L25: 0 | M25: 0 | N25: 0 | O25: 0 | P25: =SUM(G25:O25) -> 0 | Q25: =F25+P25 -> 0 | W25: =Q25-SUM(R25:V25) -> 0 | X25: =F25-R25-T25 -> 0 | AC25: =W25*33000 -> 0 | AD25: =W25*5000 -> 0 | AE25: 0 | AF25: 0 | AG25: =SUM(AB25:AD25) -> 0
B26: Graduands | C26: 0 | D26: 0 | E26: 0 | F26: =SUM(C26:E26) -> 0 | G26: 0 | H26: 0 | I26: 0 | J26: 0 | K26: 0 | L26: 0 | M26: 0 | N26: 0 | O26: 0 | P26: =SUM(G26:O26) -> 0 | Q26: =F26+P26 -> 0 | W26: =Q26-SUM(R26:V26) -> 0 | X26: =F26-R26-T26 -> 0 | AC26: =W26*33000 -> 0 | AD26: =W26*5000 -> 0 | AE26: 0 | AF26: 0 | AG26: =SUM(AB26:AD26) -> 0
B27: Total Students in FP | C27: =SUM(C22:C26) -> 0 | D27: =SUM(D22:D26) -> 0 | E27: =SUM(E22:E26) -> 0 | F27: =SUM(F22:F26) -> 0 | G27: =SUM(G22:G26) -> 0 | H27: =SUM(H22:H26) -> 0 | I27: =SUM(I22:I26) -> 0 | J27: =SUM(J22:J26) -> 0 | ... AG27: =SUM(AG22:AG26) -> 11410000
B28: 1.Total Students in faculty of Science and technology | F28: =F13+F20+F27 -> 331 | G28: =G13+G20+G27 -> 20 | H28: =H13+H20+H27 -> 30 | I28: =I13+I20+I27 -> 0 | J28: =J13+J20+J27 -> 45 | K28: =K13+K20+K27 -> 10 | L28: =L13+L20+L27 -> 0 | M28: =M13+M20+M27 -> 80 | ... AG28: =AG13+AG20+AG27 -> 142809000
B29: 2.Faculty of social work | P29: =SUM(G29:O29) -> 0 | X29: =F29-R29-T29 -> 0
B30: L8 S1&2 | C30: 0 | D30: 34 | F30: =SUM(C30:E30) -> 34 | H30: 10 | K30: 20 | N30: 10 | P30: =SUM(G30:O30) -> 40 | Q30: =F30+P30 -> 74 | W30: =Q30-SUM(R30:V30) -> 74 | X30: =F30-R30-T30 -> 34 | Y30: 10 | Z30: 20 | AA30: 10 | AB30: =((X30*375000)+(Y30*375000)+(Z30*250000)+(AA30*125000)) -> 22750000 | AC30: =W30*33000 -> 2442000 | AD30: =W30*5000 -> 370000 | AG30: =SUM(AB30:AD30) -> 25562000
B31: L8 S3&4 | C31: 0 | D31: 0 | F31: =SUM(C31:E31) -> 0 | P31: =SUM(G31:O31) -> 0 | Q31: =F31+P31 -> 0 | W31: =Q31-SUM(R31:V31) -> 0 | X31: =F31-R31-T31 -> 0 | AB31: =((X31*375000)+(Y31*375000)+(Z31*250000)+(AA31*125000)) -> 0 | AC31: =W31*33000 -> 0 | AG31: =SUM(AB31:AD31) -> 0
B32: L8 S5&6 | C32: 0 | D32: 14 | F32: =SUM(C32:E32) -> 14 | P32: =SUM(G32:O32) -> 0 | Q32: =F32+P32 -> 14 | W32: =Q32-SUM(R32:V32) -> 14 | X32: =F32-R32-T32 -> 14 | AB32: =((X32*375000)+(Y32*375000)+(Z32*250000)+(AA32*125000)) -> 5250000 | AC32: =W32*33000 -> 462000 | AG32: =SUM(AB32:AD32) -> 5712000
B33: L8 S7&8 | C33: 0 | D33: 14 | F33: =SUM(C33:E33) -> 14 | P33: =SUM(G33:O33) -> 0 | Q33: =F33+P33 -> 14 | W33: =Q33-SUM(R33:V33) -> 14 | X33: =F33-R33-T33 -> 14 | AB33: =((X33*375000)+(Y33*375000)+(Z33*250000)+(AA33*125000)) -> 5250000 | AC33: =W33*33000 -> 462000 | AE33: =W33*30000 -> 420000 | AF33: =W33*150000 -> 2100000 | AG33: =SUM(AB33:AD33) -> 5712000
B34: Graduands | F34: =SUM(C34:E34) -> 0 | P34: =SUM(G34:O34) -> 0 | Q34: =F34+P34 -> 0 | W34: =Q34-SUM(R34:V34) -> 0 | X34: =F34-R34-T34 -> 0 | AB34: =((X34*375000)+(Y34*375000)+(Z34*250000)+(AA34*125000)) -> 0 | AC34: =W34*33000 -> 0 | AG34: =SUM(AB34:AD34) -> 0
B35: Partime | C35: 0 | D35: 0 | F35: =SUM(C35:E35) -> 0 | P35: =SUM(G35:O35) -> 0 | Q35: =F35+P35 -> 0 | W35: =Q35-SUM(R35:V35) -> 0 | X35: =F35-R35-T35 -> 0 | AB35: =((X35*375000)+(Y35*375000)+(Z35*250000)+(AA35*125000)) -> 0 | AC35: =W35*33000 -> 0 | AG35: =SUM(AB35:AD35) -> 0
B36: 2.Total students Faculty of social work | C36: 0 | D36: =SUM(D30:D35) -> 62 | F36: =SUM(F30:F35) -> 62 | G36: =SUM(G30:G35) -> 0 | H36: =SUM(H30:H35) -> 10 | I36: =SUM(I30:I35) -> 0 | J36: =SUM(J30:J35) -> 0 | K36: =SUM(K30:K35) -> 20 | L36: =SUM(L30:L35) -> 0 | M36: =SUM(M30:M35) -> 0 | ... AG36: =SUM(AG30:AG35) -> 36986000
B37: 3.Faculty of Education
B38: 3.1 Educational Management and planning | P38: =SUM(G38:O38) -> 0 | Q38: =F38+P38 -> 0 | X38: =F38-R38-T38 -> 0
B39: L8 S1&2 | C39: 0 | D39: 0 | F39: =SUM(C39:E39) -> 0 | P39: =SUM(G39:O39) -> 0 | Q39: =F39+P39 -> 0 | W39: =Q39-SUM(R39:V39) -> 0 | X39: =F39-R39-T39 -> 0 | AB39: =((X39*375000)+(Y39*375000)+(Z39*250000)+(AA39*125000)) -> 0 | AC39: =W39*33000 -> 0 | AD39: =W39*5000 -> 0 | AG39: =SUM(AB39:AD39) -> 0
B40: L8 S3&4 | C40: 0 | D40: 0 | F40: =SUM(C40:E40) -> 0 | P40: =SUM(G40:O40) -> 0 | Q40: =F40+P40 -> 0 | W40: =Q40-SUM(R40:V40) -> 0 | X40: =F40-R40-T40 -> 0 | AB40: =((X40*375000)+(Y40*375000)+(Z40*250000)+(AA40*125000)) -> 0 | AC40: =W40*33000 -> 0 | AG40: =SUM(AB40:AD40) -> 0
...

Sheet INCOME EXECUTION 2024-2025
C3: Income in Details Number of students
C4: Budgeted number of students
D5: Budgeted | E5: Execution | F5: Variance | G5: % completion | H5: Rank
B6: 6 | C6: FCOM | D6: 653 | E6: 717 | F6: =E6-D6 -> 64 | G6: =E6/D6*100 -> 109.80092 | H6: 1
B7: 2 | C7: FSW | D7: 102 | E7: 105 | F7: =E7-D7 -> 3 | G7: =E7/D7*100 -> 102.94118 | H7: 2
B8: 3 | C8: FED | D8: 1695 | E8: 1536 | F8: =E8-D8 -> -159 | G8: =E8/D8*100 -> 90.619469 | H8: 3
B9: 4 | C9: FHS | D9: 841 | E9: 671 | F9: =E9-D9 -> -170 | G9: =E9/D9*100 -> 79.785969 | H9: 4
B10: 1 | C10: FST | D10: 379 | E10: 279 | F10: =E10-D10 -> -100 | G10: =E10/D10*100 -> 73.614776 | H10: 5
B11: 5 | C11: FCRS | D11: 160 | E11: 100 | F11: =E11-D11 -> -60 | G11: =E11/D11*100 -> 62.5 | H11: 6
B12: 7 | C12: PGDE | D12: 167 | E12: 34 | F12: =E12-D12 -> -133 | G12: =E12/D12*100 -> 20.359281 | H12: 7
C13: Total University | D13: =SUM(D6:D12) -> 3997 | E13: =SUM(E6:E12) -> 3442 | F13: =E13-D13 -> -555 | G13: =E13/D13*100 -> 86.114586
C14: Exisiting | E14: 2492 | F14: =E14-E13 -> -950
C15: % Increase in Number of student | E15: =(E13-E14)/E14 -> 0.3812199
E16: =D13*(1+E15) -> 5520.736
D18: =E13+950 -> 4392
C34: PROJECTS FEES
C35: Date | D35: 1470.780686
B36: Nishati Project | C36: 27.02.2025 | D36: 43786 | E36: =D36*D35 -> 64399603
B37: Fun learning consultation | C37: 27.08.2025 | D37: 3416.25 | E37: =D37*D38 -> 5735435.7
B38: Irrigation project | D38: 1678.868854 | E38: 72277194
B39: Grant Income | E39: =SUM(E36:E38) -> 1.4241223e+08

Sheet DETAILED Number of students
C2: L8 S1&2 | D2: L8 S3&4 | E2: L8 S5&6 | F2: L8 S7&8 | G2: L9 | H2: Graduands | I2: Partime | J2: Total students
A3: 1.Faculty of science and technology
A5: Department Biomedical Laboratory science | B5: Day program | C5: 22 | D5: 26 | E5: 76 | F5: 18 | I5: 0 | J5: =SUM(C5:I5) -> 142
B6: Weekend Program | C6: 0 | D6: 0 | E6: 0 | F6: 0 | I6: 0 | J6: =SUM(C6:I6) -> 0
A7: Department of computer science | B7: Day program | C7: =35+4 -> 39 | D7: 63 | E7: 8 | F7: 17 | J7: =SUM(C7:I7) -> 127
B8: Weekend Program | C8: 23 | E8: 20 | F8: 19 | J8: =SUM(C8:I8) -> 62
J9: =SUM(J5:J8) -> 331
A10: 2.Faculty of social work | B10: Day program | C10: 0 | D10: 0 | E10: 0 | F10: 0 | I10: 0 | J10: 0
B11: Weekend Program | C11: 34 | D11: 0 | E11: 14 | F11: 14 | I11: 0 | J11: =SUM(C11:I11) -> 62 | K11: =J11-'INCOME DETAILS'!#REF! -> #REF!
J12: =SUM(J10:J11) -> 62
A13: 3.Faculty of Education
A14: Educational Management and planning | B14: Day program | C14: 0 | D14: 0 | E14: 0 | F14: 0 | G14: 0 | H14: 0 | I14: 0
B15: Weekend Program | C15: 0 | D15: 0 | E15: 0 | F15: 0 | G15: 0 | H15: 0 | I15: 0
B16: Holiday program | C16: 0 | D16: 0 | E16: 0 | F16: 0 | G16: 0 | H16: 0 | I16: 0
A17: Department of art and social science | B17: Day program | C17: 38 | D17: 98 | J17: 136
B18: Weekend Program | C18: 63 | D18: 17 | E18: 16 | F18: 12 | H18: 12 | J18: 120
B19: Holiday program | C19: 140 | E19: 5 | F19: 8 | H19: 8 | J19: 161 | K19: 137
A20: Department of Science | B20: Day program | C20: 54 | D20: 113 | J20: 167 | K20: =J17+J20 -> 303
B21: Weekend Program | C21: 16 | D21: 48 | E21: 56 | F21: 33 | H21: 33 | J21: 186 | K21: =K20-K19 -> 166
B22: Holiday program | C22: 137 | E22: 69 | F22: 47 | H22: 47 | J22: 300
A23: 4.Faculty of public health and Human Nutrition | J23: =SUM(J14:J22) -> 1070
A24: Public Health | B24: Day program | E24: 16 | F24: 45 | J24: =SUM(C24:I24) -> 61
B25: Weekend Program | J25: =SUM(C25:I25) -> 0
A26: Human Nutrition | B26: Day program | D26: 5 | J26: =SUM(C26:I26) -> 5
B27: Weekend Program | J27: =SUM(C27:I27) -> 0
A28: Nursing | B28: Day program | C28: =43+40 -> 83 | J28: =SUM(C28:I28) -> 83
B29: Weekend Program | J29: =SUM(C29:I29) -> 0
A30: Midwifery | B30: Day program | C30: =100+100 -> 200 | J30: =SUM(C30:I30) -> 200
B31: Weekend Program | J31: =SUM(C31:I31) -> 0
J32: =SUM(J24:J31) -> 349
A33: 5. Faculty of Catechesis | B33: Day program | C33: 57 | D33: 0 | E33: 30 | F33: 32 | I33: 1 | J33: =SUM(C33:I33) -> 120
B34: Weekend Program | C34: 0 | D34: 0 | E34: 0 | F34: 0 | J34: =SUM(C34:I34) -> 0
J35: =SUM(J33:J34) -> 120
A36: 6.Faculty of commerce | B36: Day program | C36: 40 | D36: 113 | H36: 18 | J36: =SUM(C36:I36) -> 171
B37: Weekend Program | C37: 27 | D37: 101 | E37: 48 | F37: 74 | H37: 62 | J37: =SUM(C37:I37) -> 312
J38: =SUM(J36:J37) -> 483
A39: 7.Postgraduate students
B40: Huye campus | G40: 70 | J40: =SUM(G40:I40) -> 70
B41: Ngoma Learning center | G41: 7 | J41: =SUM(G41:I41) -> 7
J42: =SUM(J40:J41) -> 77
...

Sheet Sheet1
C2: L8 S1&2 | D2: L8 S3&4 | E2: L8 S5&6 | F2: L8 S7&8 | G2: L9 | H2: Graduands | I2: Partime | J2: Total students
A3: 3.Faculty of Education
A4: Educational Management and planning | B4: Day program | C4: 0 | D4: 0 | E4: 0 | F4: 0 | G4: 0 | H4: 0 | I4: 0
B5: Weekend Program | C5: 0 | D5: 0 | E5: 0 | F5: 0 | G5: 0 | H5: 0 | I5: 0
B6: Holiday program | C6: 0 | D6: 0 | E6: 0 | F6: 0 | G6: 0 | H6: 0 | I6: 0
A7: Department of art and social science | B7: Day program | C7: 38 | D7: 98 | J7: 136
B8: Weekend Program | C8: 63 | D8: 17 | E8: 16 | F8: 12 | H8: 12 | J8: 120
B9: Holiday program | C9: 140 | E9: 5 | F9: 8 | H9: 8 | J9: 161
A10: Department of Science | B10: Day program | C10: 54 | D10: 113 | J10: 167
B11: Weekend Program | C11: 16 | D11: 48 | E11: 56 | F11: 33 | H11: 33 | J11: 186
B12: Holiday program | C12: 137 | E12: 69 | F12: 47 | H12: 47 | J12: 300
D16: 3.Faculty of Education | E16: Educational Management and planning | H16: Department of art and social science | K16: Department of Science
E17: Day program | F17: Weekend Program | G17: Holiday program | H17: Day program | I17: Weekend Program | J17: Holiday program | K17: Day program | L17: Weekend Program | M17: Holiday program
C18: L8 S1&2 | E18: 0 | F18: 0 | G18: 0 | H18: 38 | I18: 63 | J18: 140 | K18: 54 | L18: 16 | M18: 137
C19: L8 S3&4 | E19: 0 | F19: 0 | G19: 0 | H19: 98 | I19: 17 | K19: 113 | L19: 48
C20: L8 S5&6 | E20: 0 | F20: 0 | G20: 0 | I20: 16 | J20: 5 | L20: 56 | M20: 69
C21: L8 S7&8 | E21: 0 | F21: 0 | G21: 0 | I21: 12 | J21: 8 | L21: 33 | M21: 47
C22: L9 | E22: 0 | F22: 0 | G22: 0
C23: Graduands | E23: 0 | F23: 0 | G23: 0 | I23: 12 | J23: 8 | L23: 33 | M23: 47
C24: Partime | E24: 0 | F24: 0 | G24: 0
C25: Total students | H25: 136 | I25: 120 | J25: 161 | K25: 167 | L25: 186 | M25: 300

Sheet Communication fees
A1: Communication fee Policy
A2: Rector | B2: =20000*2 -> 40000
A3: Vice-Rector | B3: 20000
A4: DAF | B4: 20000
A5: DOQ | B5: 15000
A6: Dean of FCRS | B6: 10000
A7: Dean of FED | B7: 10000
A8: Dean of FST | B8: 10000
A9: Dean of FCOM | B9: 10000
A10: Dean of FSW | B10: 10000
A11: Dean of FPHHN | B11: 10000
A12: Dean of students | B12: 10000
A13: Academic Registrar | B13: 10000
A14: Academic secretaries FCRS | B14: 10000
... A46: Driver 2 | B46: 3000
B47: =SUM(B2:B46) -> 466000

Sheet Responsability allowance
A1: Responsibility allowance
A2: Dean of FCRS | B2: 200000
A3: Dean of FED | B3: 200000
A4: Dean of FST | B4: 200000
A5: Dean of FCOM | B5: 200000
A6: Dean of FSW | B6: 200000
A7: Dean of FPHHN | B7: 200000
A8: Academic secretaries FCRS | B8: 150000
A9: Academic secretaries FED | B9: 150000
A10: Academic secretaries FST | B10: 150000
A11: Academic secretaries FCOM | B11: 150000
A12: Academic secretaries FSW | B12: 150000
A13: Academic secretaries FPHHN | B13: 150000
... A23: HOD HN&PH | B23: 150000
B24: =SUM(B2:B23) -> 3600000

Sheet Sheet5
A1: Panel fees
C2: Supervisor | D2: Panel members
A3: Number of graduates | B3: 260 | C3: =B3*15000 -> 3900000 | D3: =B3*2*10000 -> 5200000 | E3: =C3+D3 -> 9100000

Sheet Part-time staff cost
B4: Part-time
A5: FCRS | B5: 3574075
A6: FSW | B6: 3522960
A7: FST | B7: 2253360
A8: FPHHN | B8: 2419200
A9: FCOM | B9: 4094880
A10: FED | B10: 73274100
B11: 89138575
A12: 0.083 | B12: =B11*A12 -> 7398501.7
B13: =B11+B12 -> 96537077

Sheet STAFF COST DETAILS
A1: Proposed Salary structure | B1: Proposed new structure | C1: Existing structure | D1: Difference
A2: Senior Lecturer | B2: 1081433.7 | C2: 1029936.9 | D2: =B2-C2 -> 51496.843
A3: Lecturer | B3: 772600.95 | C3: 735810.43 | D3: =B3-C3 -> 36790.521
A4: Ass Lecturer | B4: 617402.25 | C4: 588002.14 | D4: =B4-C4 -> 29400.107
A5: Tutorial Ass | B5: 517495.5 | C5: 492853 | D5: =B5-C5 -> 24642.5
A7: This change of increase of 5% of basic salary will have overall impact which the following:
A8: Total staff cost will increase Monthly by:
A9: Academic staff | B9: =--893988.285714287 -> 893988.29
A10: Administratif staff | B10: 653976.13
A11: Total Monthly Increase | B11: =SUM(B9:B10) -> 1547964.4 | C11: 1547964.4
A12: Total annual increase in staff | B12: =B11*12 -> 18575573 | C12: 18575573
